Workbook

Sheet Amostragem
A1: Parâmetro | B1: Valor | C1: Fórmula/critério | D1: Observação
A2: N | B2: 5571 | C2: Base oficial IBGE | D2: IBGE – DTB 2025 – Tabelas da Divisão Territorial Brasileira: total de 5.570 municípios
A3: Z | B3: 1.96 | C3: Valor crítico aproximado para 95% de confiança | D3: Valor crítico da distribuição normal padrão para 95% de confiança
A4: p | B4: 0.5 | C4: Parâmetro conservador | D4: Cochran (1977): adoção conservadora de p = 0,5 quando não há proporção prévia conhecida
A5: q | B5: =1-B4 -> 0.5 | C5: q = 1 - p | D5: Derivado de p: q = 1 - p
A6: e | B6: 0.05 | C6: Erro amostral de 5% | D6: Critério metodológico definido no artigo: erro amostral de 5%
A7: n0 | B7: =(B3^2*B4*B5)/(B6^2) -> 384.16 | C7: n0 = (Z² × p × q) / e² | D7: Cochran (1977): fórmula para tamanho inicial de amostra para proporções
A8: n corrigido | B8: =B7/(1+((B7-1)/B2)) -> 359.43867 | C8: n = n0 / [1 + ((n0 - 1) / N)] | D8: Cochran (1977): correção para população finita
A9: n final | B9: =ROUNDUP(B8,0) -> 360 | C9: Arredondamento para cima | D9: Critério operacional do estudo: arredondamento para cima

Sheet Base DTB 2025 IBGE
A1: UF | B1: Nome_UF | C1: Região Geográfica Intermediária | D1: Nome Região Geográfica Intermediária | E1: Região Geográfica Imediata | F1: Nome Região Geográfica Imediata | G1: Município | H1: Código Município Completo | I1: Nome_Município | J1: Região
A2: 11 | B2: Rondônia | C2: 1102 | D2: Ji-Paraná | E2: 110005 | F2: Cacoal | G2: 00015 | H2: 1100015 | I2: Alta Floresta D'Oeste | J2: =IF(AND(VALUE(LEFT(H2,2))>=11,VALUE(LEFT(H2,2))<=17),"Norte",IF(AND(VALUE(LEFT(H2,2))>=21,VALUE(LEFT(H2,2))<=29),"Nordeste",IF(AND(VALUE(LEFT(H2,2))>=31,VALUE(LEFT(H2,2))<=35),"Sudeste",IF(AND(VALUE(LEFT(H2,2))>=41,VALUE(LEFT(H2,2))<=43),"Sul",IF(AND(VALUE(LEFT(H2,2))>=50,VALUE(LEFT(H2,2))<=53),"Centro-Oeste","Verificar"))))) -> Norte
A3: 11 | B3: Rondônia | C3: 1102 | D3: Ji-Paraná | E3: 110005 | F3: Cacoal | G3: 00379 | H3: 1100379 | I3: Alto Alegre dos Parecis | J3: =IF(AND(VALUE(LEFT(H3,2))>=11,VALUE(LEFT(H3,2))<=17),"Norte",IF(AND(VALUE(LEFT(H3,2))>=21,VALUE(LEFT(H3,2))<=29),"Nordeste",IF(AND(VALUE(LEFT(H3,2))>=31,VALUE(LEFT(H3,2))<=35),"Sudeste",IF(AND(VALUE(LEFT(H3,2))>=41,VALUE(LEFT(H3,2))<=43),"Sul",IF(AND(VALUE(LEFT(H3,2))>=50,VALUE(LEFT(H3,2))<=53),"Centro-Oeste","Verificar"))))) -> Norte
A4: 11 | B4: Rondônia | C4: 1101 | D4: Porto Velho | E4: 110002 | F4: Ariquemes | G4: 00403 | H4: 1100403 | I4: Alto Paraíso | J4: =IF(AND(VALUE(LEFT(H4,2))>=11,VALUE(LEFT(H4,2))<=17),"Norte",IF(AND(VALUE(LEFT(H4,2))>=21,VALUE(LEFT(H4,2))<=29),"Nordeste",IF(AND(VALUE(LEFT(H4,2))>=31,VALUE(LEFT(H4,2))<=35),"Sudeste",IF(AND(VALUE(LEFT(H4,2))>=41,VALUE(LEFT(H4,2))<=43),"Sul",IF(AND(VALUE(LEFT(H4,2))>=50,VALUE(LEFT(H4,2))<=53),"Centro-Oeste","Verificar"))))) -> Norte
A5: 11 | B5: Rondônia | C5: 1102 | D5: Ji-Paraná | E5: 110004 | F5: Ji-Paraná | G5: 00346 | H5: 1100346 | I5: Alvorada D'Oeste | J5: =IF(AND(VALUE(LEFT(H5,2))>=11,VALUE(LEFT(H5,2))<=17),"Norte",IF(AND(VALUE(LEFT(H5,2))>=21,VALUE(LEFT(H5,2))<=29),"Nordeste",IF(AND(VALUE(LEFT(H5,2))>=31,VALUE(LEFT(H5,2))<=35),"Sudeste",IF(AND(VALUE(LEFT(H5,2))>=41,VALUE(LEFT(H5,2))<=43),"Sul",IF(AND(VALUE(LEFT(H5,2))>=50,VALUE(LEFT(H5,2))<=53),"Centro-Oeste","Verificar"))))) -> Norte
A6: 11 | B6: Rondônia | C6: 1101 | D6: Porto Velho | E6: 110002 | F6: Ariquemes | G6: 00023 | H6: 1100023 | I6: Ariquemes | J6: =IF(AND(VALUE(LEFT(H6,2))>=11,VALUE(LEFT(H6,2))<=17),"Norte",IF(AND(VALUE(LEFT(H6,2))>=21,VALUE(LEFT(H6,2))<=29),"Nordeste",IF(AND(VALUE(LEFT(H6,2))>=31,VALUE(LEFT(H6,2))<=35),"Sudeste",IF(AND(VALUE(LEFT(H6,2))>=41,VALUE(LEFT(H6,2))<=43),"Sul",IF(AND(VALUE(LEFT(H6,2))>=50,VALUE(LEFT(H6,2))<=53),"Centro-Oeste","Verificar"))))) -> Norte
A7: 11 | B7: Rondônia | C7: 1101 | D7: Porto Velho | E7: 110002 | F7: Ariquemes | G7: 00452 | H7: 1100452 | I7: Buritis | J7: =IF(AND(VALUE(LEFT(H7,2))>=11,VALUE(LEFT(H7,2))<=17),"Norte",IF(AND(VALUE(LEFT(H7,2))>=21,VALUE(LEFT(H7,2))<=29),"Nordeste",IF(AND(VALUE(LEFT(H7,2))>=31,VALUE(LEFT(H7,2))<=35),"Sudeste",IF(AND(VALUE(LEFT(H7,2))>=41,VALUE(LEFT(H7,2))<=43),"Sul",IF(AND(VALUE(LEFT(H7,2))>=50,VALUE(LEFT(H7,2))<=53),"Centro-Oeste","Verificar"))))) -> Norte
A8: 11 | B8: Rondônia | C8: 1102 | D8: Ji-Paraná | E8: 110006 | F8: Vilhena | G8: 00031 | H8: 1100031 | I8: Cabixi | J8: =IF(AND(VALUE(LEFT(H8,2))>=11,VALUE(LEFT(H8,2))<=17),"Norte",IF(AND(VALUE(LEFT(H8,2))>=21,VALUE(LEFT(H8,2))<=29),"Nordeste",IF(AND(VALUE(LEFT(H8,2))>=31,VALUE(LEFT(H8,2))<=35),"Sudeste",IF(AND(VALUE(LEFT(H8,2))>=41,VALUE(LEFT(H8,2))<=43),"Sul",IF(AND(VALUE(LEFT(H8,2))>=50,VALUE(LEFT(H8,2))<=53),"Centro-Oeste","Verificar"))))) -> Norte
A9: 11 | B9: Rondônia | C9: 1101 | D9: Porto Velho | E9: 110002 | F9: Ariquemes | G9: 00601 | H9: 1100601 | I9: Cacaulândia | J9: =IF(AND(VALUE(LEFT(H9,2))>=11,VALUE(LEFT(H9,2))<=17),"Norte",IF(AND(VALUE(LEFT(H9,2))>=21,VALUE(LEFT(H9,2))<=29),"Nordeste",IF(AND(VALUE(LEFT(H9,2))>=31,VALUE(LEFT(H9,2))<=35),"Sudeste",IF(AND(VALUE(LEFT(H9,2))>=41,VALUE(LEFT(H9,2))<=43),"Sul",IF(AND(VALUE(LEFT(H9,2))>=50,VALUE(LEFT(H9,2))<=53),"Centro-Oeste","Verificar"))))) -> Norte
A10: 11 | B10: Rondônia | C10: 1102 | D10: Ji-Paraná | E10: 110005 | F10: Cacoal | G10: 00049 | H10: 1100049 | I10: Cacoal | J10: =IF(AND(VALUE(LEFT(H10,2))>=11,VALUE(LEFT(H10,2))<=17),"Norte",IF(AND(VALUE(LEFT(H10,2))>=21,VALUE(LEFT(H10,2))<=29),"Nordeste",IF(AND(VALUE(LEFT(H10,2))>=31,VALUE(LEFT(H10,2))<=35),"Sudeste",IF(AND(VALUE(LEFT(H10,2))>=41,VALUE(LEFT(H10,2))<=43),"Sul",IF(AND(VALUE(LEFT(H10,2))>=50,VALUE(LEFT(H10,2))<=53),"Centro-Oeste","Verificar"))))) -> Norte
A11: 11 | B11: Rondônia | C11: 1101 | D11: Porto Velho | E11: 110002 | F11: Ariquemes | G11: 00700 | H11: 1100700 | I11: Campo Novo de Rondônia | J11: =IF(AND(VALUE(LEFT(H11,2))>=11,VALUE(LEFT(H11,2))<=17),"Norte",IF(AND(VALUE(LEFT(H11,2))>=21,VALUE(LEFT(H11,2))<=29),"Nordeste",IF(AND(VALUE(LEFT(H11,2))>=31,VALUE(LEFT(H11,2))<=35),"Sudeste",IF(AND(VALUE(LEFT(H11,2))>=41,VALUE(LEFT(H11,2))<=43),"Sul",IF(AND(VALUE(LEFT(H11,2))>=50,VALUE(LEFT(H11,2))<=53),"Centro-Oeste","Verificar"))))) -> Norte
A12: 11 | B12: Rondônia | C12: 1101 | D12: Porto Velho | E12: 110001 | F12: Porto Velho | G12: 00809 | H12: 1100809 | I12: Candeias do Jamari | J12: =IF(AND(VALUE(LEFT(H12,2))>=11,VALUE(LEFT(H12,2))<=17),"Norte",IF(AND(VALUE(LEFT(H12,2))>=21,VALUE(LEFT(H12,2))<=29),"Nordeste",IF(AND(VALUE(LEFT(H12,2))>=31,VALUE(LEFT(H12,2))<=35),"Sudeste",IF(AND(VALUE(LEFT(H12,2))>=41,VALUE(LEFT(H12,2))<=43),"Sul",IF(AND(VALUE(LEFT(H12,2))>=50,VALUE(LEFT(H12,2))<=53),"Centro-Oeste","Verificar"))))) -> Norte
A13: 11 | B13: Rondônia | C13: 1102 | D13: Ji-Paraná | E13: 110005 | F13: Cacoal | G13: 00908 | H13: 1100908 | I13: Castanheiras | J13: =IF(AND(VALUE(LEFT(H13,2))>=11,VALUE(LEFT(H13,2))<=17),"Norte",IF(AND(VALUE(LEFT(H13,2))>=21,VALUE(LEFT(H13,2))<=29),"Nordeste",IF(AND(VALUE(LEFT(H13,2))>=31,VALUE(LEFT(H13,2))<=35),"Sudeste",IF(AND(VALUE(LEFT(H13,2))>=41,VALUE(LEFT(H13,2))<=43),"Sul",IF(AND(VALUE(LEFT(H13,2))>=50,VALUE(LEFT(H13,2))<=53),"Centro-Oeste","Verificar"))))) -> Norte
A14: 11 | B14: Rondônia | C14: 1102 | D14: Ji-Paraná | E14: 110006 | F14: Vilhena | G14: 00056 | H14: 1100056 | I14: Cerejeiras | J14: =IF(AND(VALUE(LEFT(H14,2))>=11,VALUE(LEFT(H14,2))<=17),"Norte",IF(AND(VALUE(LEFT(H14,2))>=21,VALUE(LEFT(H14,2))<=29),"Nordeste",IF(AND(VALUE(LEFT(H14,2))>=31,VALUE(LEFT(H14,2))<=35),"Sudeste",IF(AND(VALUE(LEFT(H14,2))>=41,VALUE(LEFT(H14,2))<=43),"Sul",IF(AND(VALUE(LEFT(H14,2))>=50,VALUE(LEFT(H14,2))<=53),"Centro-Oeste","Verificar"))))) -> Norte
... A5572: 53 | B5572: Distrito Federal | C5572: 5301 | D5572: Distrito Federal | E5572: 530001 | F5572: Distrito Federal | G5572: 00108 | H5572: 5300108 | I5572: Brasília | J5572: =IF(AND(VALUE(LEFT(H5572,2))>=11,VALUE(LEFT(H5572,2))<=17),"Norte",IF(AND(VALUE(LEFT(H5572,2))>=21,VALUE(LEFT(H5572,2))<=29),"Nordeste",IF(AND(VALUE(LEFT(H5572,2))>=31,VALUE(LEFT(H5572,2))<=35),"Sudeste",IF(AND(VALUE(LEFT(H5572,2))>=41,VALUE(LEFT(H5572,2))<=43),"Sul",IF(AND(VALUE(LEFT(H5572,2))>=50,VALUE(LEFT(H5572,2))<=53),"Centro-Oeste","Verificar"))))) -> Centro-Oeste

Sheet Tabela Dinâmica Base DTB
A3: Rótulos de Linha | B3: Contagem de Município | D3: Região | E3: Municípios | F3: Proporção | G3: Amostra proporcional | H3: Amostra final
A4: Centro-Oeste | B4: 468 | D4: Centro-Oeste | E4: =B4 -> 468 | F4: =E4/$B$9 -> 0.084006462 | G4: =F4*360 -> 30.242326 | H4: =ROUNDUP(G4,0) -> 31
A5: Nordeste | B5: 1794 | D5: Nordeste | E5: =B5 -> 1794 | F5: =E5/$B$9 -> 0.32202477 | G5: =F5*360 -> 115.92892 | H5: =ROUNDUP(G5,0) -> 116
A6: Norte | B6: 450 | D6: Norte | E6: =B6 -> 450 | F6: =E6/$B$9 -> 0.080775444 | G6: =F6*360 -> 29.07916 | H6: =ROUNDUP(G6,0) -> 30
A7: Sudeste | B7: 1668 | D7: Sudeste | E7: =B7 -> 1668 | F7: =E7/$B$9 -> 0.29940765 | G7: =F7*360 -> 107.78675 | H7: =ROUNDUP(G7,0) -> 108
A8: Sul | B8: 1191 | D8: Sul | E8: =B8 -> 1191 | F8: =E8/$B$9 -> 0.21378568 | G8: =F8*360 -> 76.962843 | H8: =ROUNDUP(G8,0) -> 77
A9: Total Geral | B9: 5571 | D9: Total | E9: =SUM(E4:E8) -> 5571 | F9: =SUM(F4:F8) -> 1 | G9: =SUM(G4:G8) -> 360 | H9: =SUM(H4:H8) -> 362

Sheet Sorteio DTB 2025 IBGE
A1: Código_UF | B1: Nome_UF | C1: Código_Município Completo | D1: Código_Município | E1: Nome_Município | F1: Região | G1: Chave Aleatória | H1: Selecionado
A2: 51 | B2: Mato Grosso | C2: 5107909 | D2: 07909 | E2: Sinop | F2: =IF(OR(B2="Rondônia",B2="Acre",B2="Amazonas",B2="Roraima",B2="Pará",B2="Amapá",B2="Tocantins"),"Norte",IF(OR(B2="Maranhão",B2="Piauí",B2="Ceará",B2="Rio Grande do Norte",B2="Paraíba",B2="Pernambuco",B2="Alagoas",B2="Sergipe",B2="Bahia"),"Nordeste",IF(OR(B2="Minas Gerais",B2="Espírito Santo",B2="Rio de Janeiro",B2="São Paulo"),"Sudeste",IF(OR(B2="Paraná",B2="Santa Catarina",B2="Rio Grande do Sul"),"Sul",IF(OR(B2="Mato Grosso do Sul",B2="Mato Grosso",B2="Goiás",B2="Distrito Federal"),"Centro-Oeste","Verificar"))))) -> Centro-Oeste | G2: 0.0025088861 | H2: Sim
A3: 51 | B3: Mato Grosso | C3: 5108402 | D3: 08402 | E3: Várzea Grande | F3: =IF(OR(B3="Rondônia",B3="Acre",B3="Amazonas",B3="Roraima",B3="Pará",B3="Amapá",B3="Tocantins"),"Norte",IF(OR(B3="Maranhão",B3="Piauí",B3="Ceará",B3="Rio Grande do Norte",B3="Paraíba",B3="Pernambuco",B3="Alagoas",B3="Sergipe",B3="Bahia"),"Nordeste",IF(OR(B3="Minas Gerais",B3="Espírito Santo",B3="Rio de Janeiro",B3="São Paulo"),"Sudeste",IF(OR(B3="Paraná",B3="Santa Catarina",B3="Rio Grande do Sul"),"Sul",IF(OR(B3="Mato Grosso do Sul",B3="Mato Grosso",B3="Goiás",B3="Distrito Federal"),"Centro-Oeste","Verificar"))))) -> Centro-Oeste | G3: 0.0042295342 | H3: Sim
A4: 52 | B4: Goiás | C4: 5206602 | D4: 06602 | E4: Cumari | F4: =IF(OR(B4="Rondônia",B4="Acre",B4="Amazonas",B4="Roraima",B4="Pará",B4="Amapá",B4="Tocantins"),"Norte",IF(OR(B4="Maranhão",B4="Piauí",B4="Ceará",B4="Rio Grande do Norte",B4="Paraíba",B4="Pernambuco",B4="Alagoas",B4="Sergipe",B4="Bahia"),"Nordeste",IF(OR(B4="Minas Gerais",B4="Espírito Santo",B4="Rio de Janeiro",B4="São Paulo"),"Sudeste",IF(OR(B4="Paraná",B4="Santa Catarina",B4="Rio Grande do Sul"),"Sul",IF(OR(B4="Mato Grosso do Sul",B4="Mato Grosso",B4="Goiás",B4="Distrito Federal"),"Centro-Oeste","Verificar"))))) -> Centro-Oeste | G4: 0.005838812 | H4: Sim
A5: 52 | B5: Goiás | C5: 5220454 | D5: 20454 | E5: Senador Canedo | F5: =IF(OR(B5="Rondônia",B5="Acre",B5="Amazonas",B5="Roraima",B5="Pará",B5="Amapá",B5="Tocantins"),"Norte",IF(OR(B5="Maranhão",B5="Piauí",B5="Ceará",B5="Rio Grande do Norte",B5="Paraíba",B5="Pernambuco",B5="Alagoas",B5="Sergipe",B5="Bahia"),"Nordeste",IF(OR(B5="Minas Gerais",B5="Espírito Santo",B5="Rio de Janeiro",B5="São Paulo"),"Sudeste",IF(OR(B5="Paraná",B5="Santa Catarina",B5="Rio Grande do Sul"),"Sul",IF(OR(B5="Mato Grosso do Sul",B5="Mato Grosso",B5="Goiás",B5="Distrito Federal"),"Centro-Oeste","Verificar"))))) -> Centro-Oeste | G5: 0.0062921544 | H5: Sim
A6: 52 | B6: Goiás | C6: 5207253 | D6: 07253 | E6: Doverlândia | F6: =IF(OR(B6="Rondônia",B6="Acre",B6="Amazonas",B6="Roraima",B6="Pará",B6="Amapá",B6="Tocantins"),"Norte",IF(OR(B6="Maranhão",B6="Piauí",B6="Ceará",B6="Rio Grande do Norte",B6="Paraíba",B6="Pernambuco",B6="Alagoas",B6="Sergipe",B6="Bahia"),"Nordeste",IF(OR(B6="Minas Gerais",B6="Espírito Santo",B6="Rio de Janeiro",B6="São Paulo"),"Sudeste",IF(OR(B6="Paraná",B6="Santa Catarina",B6="Rio Grande do Sul"),"Sul",IF(OR(B6="Mato Grosso do Sul",B6="Mato Grosso",B6="Goiás",B6="Distrito Federal"),"Centro-Oeste","Verificar"))))) -> Centro-Oeste | G6: 0.0064175894 | H6: Sim
A7: 51 | B7: Mato Grosso | C7: 5103437 | D7: 03437 | E7: Curvelândia | F7: =IF(OR(B7="Rondônia",B7="Acre",B7="Amazonas",B7="Roraima",B7="Pará",B7="Amapá",B7="Tocantins"),"Norte",IF(OR(B7="Maranhão",B7="Piauí",B7="Ceará",B7="Rio Grande do Norte",B7="Paraíba",B7="Pernambuco",B7="Alagoas",B7="Sergipe",B7="Bahia"),"Nordeste",IF(OR(B7="Minas Gerais",B7="Espírito Santo",B7="Rio de Janeiro",B7="São Paulo"),"Sudeste",IF(OR(B7="Paraná",B7="Santa Catarina",B7="Rio Grande do Sul"),"Sul",IF(OR(B7="Mato Grosso do Sul",B7="Mato Grosso",B7="Goiás",B7="Distrito Federal"),"Centro-Oeste","Verificar"))))) -> Centro-Oeste | G7: 0.0065792411 | H7: Sim
A8: 52 | B8: Goiás | C8: 5204656 | D8: 04656 | E8: Campinaçu | F8: =IF(OR(B8="Rondônia",B8="Acre",B8="Amazonas",B8="Roraima",B8="Pará",B8="Amapá",B8="Tocantins"),"Norte",IF(OR(B8="Maranhão",B8="Piauí",B8="Ceará",B8="Rio Grande do Norte",B8="Paraíba",B8="Pernambuco",B8="Alagoas",B8="Sergipe",B8="Bahia"),"Nordeste",IF(OR(B8="Minas Gerais",B8="Espírito Santo",B8="Rio de Janeiro",B8="São Paulo"),"Sudeste",IF(OR(B8="Paraná",B8="Santa Catarina",B8="Rio Grande do Sul"),"Sul",IF(OR(B8="Mato Grosso do Sul",B8="Mato Grosso",B8="Goiás",B8="Distrito Federal"),"Centro-Oeste","Verificar"))))) -> Centro-Oeste | G8: 0.008315084 | H8: Sim
A9: 52 | B9: Goiás | C9: 5213905 | D9: 13905 | E9: Mossâmedes | F9: =IF(OR(B9="Rondônia",B9="Acre",B9="Amazonas",B9="Roraima",B9="Pará",B9="Amapá",B9="Tocantins"),"Norte",IF(OR(B9="Maranhão",B9="Piauí",B9="Ceará",B9="Rio Grande do Norte",B9="Paraíba",B9="Pernambuco",B9="Alagoas",B9="Sergipe",B9="Bahia"),"Nordeste",IF(OR(B9="Minas Gerais",B9="Espírito Santo",B9="Rio de Janeiro",B9="São Paulo"),"Sudeste",IF(OR(B9="Paraná",B9="Santa Catarina",B9="Rio Grande do Sul"),"Sul",IF(OR(B9="Mato Grosso do Sul",B9="Mato Grosso",B9="Goiás",B9="Distrito Federal"),"Centro-Oeste","Verificar"))))) -> Centro-Oeste | G9: 0.010133321 | H9: Sim
A10: 50 | B10: Mato Grosso do Sul | C10: 5002704 | D10: 02704 | E10: Campo Grande | F10: =IF(OR(B10="Rondônia",B10="Acre",B10="Amazonas",B10="Roraima",B10="Pará",B10="Amapá",B10="Tocantins"),"Norte",IF(OR(B10="Maranhão",B10="Piauí",B10="Ceará",B10="Rio Grande do Norte",B10="Paraíba",B10="Pernambuco",B10="Alagoas",B10="Sergipe",B10="Bahia"),"Nordeste",IF(OR(B10="Minas Gerais",B10="Espírito Santo",B10="Rio de Janeiro",B10="São Paulo"),"Sudeste",IF(OR(B10="Paraná",B10="Santa Catarina",B10="Rio Grande do Sul"),"Sul",IF(OR(B10="Mato Grosso do Sul",B10="Mato Grosso",B10="Goiás",B10="Distrito Federal"),"Centro-Oeste","Verificar"))))) -> Centro-Oeste | G10: 0.011278 | H10: Sim
A11: 52 | B11: Goiás | C11: 5210802 | D11: 10802 | E11: Itajá | F11: =IF(OR(B11="Rondônia",B11="Acre",B11="Amazonas",B11="Roraima",B11="Pará",B11="Amapá",B11="Tocantins"),"Norte",IF(OR(B11="Maranhão",B11="Piauí",B11="Ceará",B11="Rio Grande do Norte",B11="Paraíba",B11="Pernambuco",B11="Alagoas",B11="Sergipe",B11="Bahia"),"Nordeste",IF(OR(B11="Minas Gerais",B11="Espírito Santo",B11="Rio de Janeiro",B11="São Paulo"),"Sudeste",IF(OR(B11="Paraná",B11="Santa Catarina",B11="Rio Grande do Sul"),"Sul",IF(OR(B11="Mato Grosso do Sul",B11="Mato Grosso",B11="Goiás",B11="Distrito Federal"),"Centro-Oeste","Verificar"))))) -> Centro-Oeste | G11: 0.012106377 | H11: Sim
A12: 50 | B12: Mato Grosso do Sul | C12: 5007208 | D12: 07208 | E12: Rio Brilhante | F12: =IF(OR(B12="Rondônia",B12="Acre",B12="Amazonas",B12="Roraima",B12="Pará",B12="Amapá",B12="Tocantins"),"Norte",IF(OR(B12="Maranhão",B12="Piauí",B12="Ceará",B12="Rio Grande do Norte",B12="Paraíba",B12="Pernambuco",B12="Alagoas",B12="Sergipe",B12="Bahia"),"Nordeste",IF(OR(B12="Minas Gerais",B12="Espírito Santo",B12="Rio de Janeiro",B12="São Paulo"),"Sudeste",IF(OR(B12="Paraná",B12="Santa Catarina",B12="Rio Grande do Sul"),"Sul",IF(OR(B12="Mato Grosso do Sul",B12="Mato Grosso",B12="Goiás",B12="Distrito Federal"),"Centro-Oeste","Verificar"))))) -> Centro-Oeste | G12: 0.015918488 | H12: Sim
A13: 52 | B13: Goiás | C13: 5214838 | D13: 14838 | E13: Nova Crixás | F13: =IF(OR(B13="Rondônia",B13="Acre",B13="Amazonas",B13="Roraima",B13="Pará",B13="Amapá",B13="Tocantins"),"Norte",IF(OR(B13="Maranhão",B13="Piauí",B13="Ceará",B13="Rio Grande do Norte",B13="Paraíba",B13="Pernambuco",B13="Alagoas",B13="Sergipe",B13="Bahia"),"Nordeste",IF(OR(B13="Minas Gerais",B13="Espírito Santo",B13="Rio de Janeiro",B13="São Paulo"),"Sudeste",IF(OR(B13="Paraná",B13="Santa Catarina",B13="Rio Grande do Sul"),"Sul",IF(OR(B13="Mato Grosso do Sul",B13="Mato Grosso",B13="Goiás",B13="Distrito Federal"),"Centro-Oeste","Verificar"))))) -> Centro-Oeste | G13: 0.016464116 | H13: Sim
... A5572: 42 | B5572: Santa Catarina | C5572: 4214409 | D5572: 14409 | E5572: Rio das Antas | F5572: =IF(OR(B5572="Rondônia",B5572="Acre",B5572="Amazonas",B5572="Roraima",B5572="Pará",B5572="Amapá",B5572="Tocantins"),"Norte",IF(OR(B5572="Maranhão",B5572="Piauí",B5572="Ceará",B5572="Rio Grande do Norte",B5572="Paraíba",B5572="Pernambuco",B5572="Alagoas",B5572="Sergipe",B5572="Bahia"),"Nordeste",IF(OR(B5572="Minas Gerais",B5572="Espírito Santo",B5572="Rio de Janeiro",B5572="São Paulo"),"Sudeste",IF(OR(B5572="Paraná",B5572="Santa Catarina",B5572="Rio Grande do Sul"),"Sul",IF(OR(B5572="Mato Grosso do Sul",B5572="Mato Grosso",B5572="Goiás",B5572="Distrito Federal"),"Centro-Oeste","Verificar"))))) -> Sul | G5572: 0.99984751 | H5572: Não

Sheet Tabela Dinâmica Sorteio DTB
A1: Selecionado | B1: Sim
A3: Rótulos de Linha
A4: Centro-Oeste
A5: Nordeste
A6: Norte
A7: Sudeste
A8: Sul
A9: Total Geral

Sheet Amostra Sorteada
A1: Código_UF | B1: Nome_UF | C1: Código_Município Completo | D1: Código_Município | E1: Nome_Município | F1: Região | G1: Chave Aleatória | H1: Selecionado | I1: Site Encontrado | J1: Confiavel | K1: Status | L1: URL | M1: Observação
A2: 51 | B2: Mato Grosso | C2: 5107909 | D2: 07909 | E2: Sinop | F2: Centro-Oeste | G2: 0.0025088861 | H2: Sim | I2: Sim | J2: Sim | K2: Apto | L2: https://www.sinop.mt.gov.br/
A3: 51 | B3: Mato Grosso | C3: 5108402 | D3: 08402 | E3: Várzea Grande | F3: Centro-Oeste | G3: 0.0042295342 | H3: Sim | I3: Sim | J3: Sim | K3: Apto | L3: https://www.varzeagrande.mt.gov.br/
A4: 52 | B4: Goiás | C4: 5206602 | D4: 06602 | E4: Cumari | F4: Centro-Oeste | G4: 0.005838812 | H4: Sim | I4: Sim | J4: Sim | K4: Apto | L4: https://cumari.go.gov.br/
A5: 52 | B5: Goiás | C5: 5220454 | D5: 20454 | E5: Senador Canedo | F5: Centro-Oeste | G5: 0.0062921544 | H5: Sim | I5: Sim | J5: Sim | K5: Apto | L5: https://senadorcanedo.go.gov.br/
A6: 52 | B6: Goiás | C6: 5207253 | D6: 07253 | E6: Doverlândia | F6: Centro-Oeste | G6: 0.0064175894 | H6: Sim | I6: Sim | J6: Sim | K6: Apto | L6: https://doverlandia.go.gov.br/
A7: 51 | B7: Mato Grosso | C7: 5103437 | D7: 03437 | E7: Curvelândia | F7: Centro-Oeste | G7: 0.0065792411 | H7: Sim | I7: Sim | J7: Sim | K7: Apto | L7: https://www.curvelandia.mt.gov.br/
A8: 52 | B8: Goiás | C8: 5204656 | D8: 04656 | E8: Campinaçu | F8: Centro-Oeste | G8: 0.008315084 | H8: Sim | I8: Sim | J8: Sim | K8: Apto | L8: https://www.campinacu.go.gov.br/
A9: 52 | B9: Goiás | C9: 5213905 | D9: 13905 | E9: Mossâmedes | F9: Centro-Oeste | G9: 0.010133321 | H9: Sim | I9: Sim | J9: Sim | K9: Apto | L9: http://mossamedes.go.gov.br/
A10: 50 | B10: Mato Grosso do Sul | C10: 5002704 | D10: 02704 | E10: Campo Grande | F10: Centro-Oeste | G10: 0.011278 | H10: Sim | I10: Sim | J10: Sim | K10: Apto | L10: https://www.campogrande.ms.gov.br/
A11: 52 | B11: Goiás | C11: 5210802 | D11: 10802 | E11: Itajá | F11: Centro-Oeste | G11: 0.012106377 | H11: Sim | I11: Sim | J11: Sim | K11: Apto | L11: https://itaja.go.gov.br/
A12: 50 | B12: Mato Grosso do Sul | C12: 5007208 | D12: 07208 | E12: Rio Brilhante | F12: Centro-Oeste | G12: 0.015918488 | H12: Sim | I12: Sim | J12: Sim | K12: Apto | L12: https://riobrilhante.ms.gov.br/
A13: 52 | B13: Goiás | C13: 5214838 | D13: 14838 | E13: Nova Crixás | F13: Centro-Oeste | G13: 0.016464116 | H13: Sim | I13: Sim | J13: Sim | K13: Apto | L13: https://novacrixas.go.gov.br/
... A45: 24 | B45: Rio Grande do Norte | C45: 2407500 | D45: 07500 | E45: Maxaranguape | F45: Nordeste | G45: 0.0069536988 | H45: Sim | I45: Sim | J45: Sim | K45: Apto | L45: https://www.maxaranguape.rn.gov.br/
A46: 22 | B46: Piauí | C46: 2205409 | D46: 05409 | E46: Joaquim Pires | F46: Nordeste | G46: 0.009620316 | H46: Sim | I46: Sim | J46: Não | K46: Substituir | L46: https://joaquimpires.pi.gov.br/ | M46: Site fora do ar
A47: 22 | B47: Piauí | C47: 2209971 | D47: 09971 | E47: São João do Arraial | F47: Nordeste | G47: 0.0096880157 | H47: Sim | I47: Sim | J47: Sim | K47: Apto | L47: https://saojoaodoarraial.pi.gov.br/
A48: 21 | B48: Maranhão | C48: 2103174 | D48: 03174 | E48: Centro Novo do Maranhão | F48: Nordeste | G48: 0.0097961295 | H48: Sim | I48: Sim | J48: Sim | K48: Apto | L48: https://www.centronovo.ma.gov.br/
A49: 23 | B49: Ceará | C49: 2313955 | D49: 13955 | E49: Varjota | F49: Nordeste | G49: 0.010117978 | H49: Sim | I49: Sim | J49: Sim | K49: Apto | L49: https://varjota.ce.gov.br/
A50: 26 | B50: Pernambuco | C50: 2609006 | D50: 09006 | E50: Macaparana | F50: Nordeste | G50: 0.011020208 | H50: Sim | I50: Sim | J50: Sim | K50: Apto | L50: https://macaparana.pe.gov.br/
A51: 25 | B51: Paraíba | C51: 2510659 | D51: 10659 | E51: Parari | F51: Nordeste | G51: 0.011139348 | H51: Sim | I51: Sim | J51: Sim | K51: Apto | L51: https://parari.pb.gov.br/
A52: 23 | B52: Ceará | C52: 2303006 | D52: 03006 | E52: Caridade | F52: Nordeste | G52: 0.011296273 | H52: Sim | I52: Sim | J52: Sim | K52: Apto | L52: https://caridade.ce.gov.br/
A53: 25 | B53: Paraíba | C53: 2512705 | D53: 12705 | E53: Remígio | F53: Nordeste | G53: 0.012017221 | H53: Sim | I53: Sim | J53: Sim | K53: Apto | L53: https://remigio.pb.gov.br/
A54: 29 | B54: Bahia | C54: 2929107 | D54: 29107 | E54: São Felipe | F54: Nordeste | G54: 0.01217146 | H54: Sim | I54: Sim | J54: Sim | K54: Apto | L54: https://saofelipe.ba.gov.br/
A55: 24 | B55: Rio Grande do Norte | C55: 2404408 | D55: 04408 | E55: Grossos | F55: Nordeste | G55: 0.013497747 | H55: Sim | I55: Sim | J55: Sim | K55: Apto | L55: https://www.grossos.rn.gov.br/
A56: 24 | B56: Rio Grande do Norte | C56: 2411007 | D56: 11007 | E56: Rodolfo Fernandes | F56: Nordeste | G56: 0.014288733 | H56: Sim | I56: Sim | J56: Sim | K56: Apto | L56: https://www.rodolfofernandes.rn.gov.br/
A57: 22 | B57: Piauí | C57: 2202554 | D57: 02554 | E57: Caridade do Piauí | F57: Nordeste | G57: 0.014547672 | H57: Sim | I57: Sim | J57: Não | K57: Substituir | L57: https://caridadedopiaui.pi.gov.br/ | M57: Site fora do ar
A58: 22 | B58: Piauí | C58: 2204352 | D58: 04352 | E58: Geminiano | F58: Nordeste | G58: 0.014697646 | H58: Sim | I58: Sim | J58: Sim | K58: Apto | L58: https://geminiano.pi.gov.br/
A59: 29 | B59: Bahia | C59: 2918803 | D59: 18803 | E59: Laje | F59: Nordeste | G59: 0.014827922 | H59: Sim | I59: Sim | J59: Sim | K59: Apto | L59: https://laje.ba.gov.br/
A60: 29 | B60: Bahia | C60: 2918555 | D60: 18555 | E60: Jussari | F60: Nordeste | G60: 0.015081429 | H60: Sim | I60: Sim | J60: Sim | K60: Apto | L60: https://jussari.ba.gov.br/
A61: 29 | B61: Bahia | C61: 2923704 | D61: 23704 | E61: Paratinga | F61: Nordeste | G61: 0.015104391 | H61: Sim | I61: Sim | J61: Sim | K61: Apto | L61: https://www.paratinga.ba.gov.br/
A62: 29 | B62: Bahia | C62: 2923209 | D62: 23209 | E62: Oliveira dos Brejinhos | F62: Nordeste | G62: 0.015397334 | H62: Sim | I62: Sim | J62: Sim | K62: Apto | L62: https://oliveiradosbrejinhos.ba.gov.br/
A63: 29 | B63: Bahia | C63: 2919058 | D63: 19058 | E63: Lajedo do Tabocal | F63: Nordeste | G63: 0.016766914 | H63: Sim | I63: Sim | J63: Sim | K63: Apto | L63: https://www.lagedodotabocal.ba.gov.br/
A64: 24 | B64: Rio Grande do Norte | C64: 2407104 | D64: 07104 | E64: Macaíba | F64: Nordeste | G64: 0.017288691 | H64: Sim | I64: Sim | J64: Sim | K64: Apto | L64: https://macaiba.rn.gov.br/
A65: 22 | B65: Piauí | C65: 2210375 | D65: 10375 | E65: São Luis do Piauí | F65: Nordeste | G65: 0.018306375 | H65: Sim | I65: Sim | J65: Sim | K65: Apto | L65: https://saoluisdopiaui.pi.gov.br/
A66: 22 | B66: Piauí | C66: 2202901 | D66: 02901 | E66: Corrente | F66: Nordeste | G66: 0.018826734 | H66: Sim | I66: Sim | J66: Sim | K66: Apto | L66: https://corrente.pi.gov.br/
A67: 22 | B67: Piauí | C67: 2205359 | D67: 05359 | E67: João Costa | F67: Nordeste | G67: 0.019374717 | H67: Sim | I67: Sim | J67: Sim | K67: Apto | L67: https://joaocosta.pi.gov.br/
A68: 23 | B68: Ceará | C68: 2308708 | D68: 08708 | E68: Morada Nova | F68: Nordeste | G68: 0.019434521 | H68: Sim | I68: Sim | J68: Sim | K68: Apto | L68: https://moradanova.ce.gov.br/
A69: 27 | B69: Alagoas | C69: 2702900 | D69: 02900 | E69: Girau do Ponciano | F69: Nordeste | G69: 0.020582969 | H69: Sim | I69: Sim | J69: Sim | K69: Apto | L69: https://giraudoponciano.al.gov.br/
... A71: 27 | B71: Alagoas | C71: 2706422 | D71: 06422 | E71: Pariconha | F71: Nordeste | G71: 0.022546673 | H71: Sim | I71: Sim | J71: Sim | K71: Apto | L71: https://pariconha.al.gov.br/
A72: 22 | B72: Piauí | C72: 2204550 | D72: 04550 | E72: Guaribas | F72: Nordeste | G72: 0.022935805 | H72: Sim | I72: Sim | J72: Não | K72: Substituir | L72: https://guaribas.pi.gov.br/ | M72: Site sem certificado de segurança SSL
...

Sheet Tabela 4714 do SIDRA IBGE
A1: Nível | B1: Cód. | C1: Município | D1: Quantidade | E1: Dado
A2: MU | B2: 1100015 | C2: Alta Floresta D'Oeste (RO) | D2: 21494 | E2: Pessoas
A3: MU | B3: 1100023 | C3: Ariquemes (RO) | D3: 96833 | E3: Pessoas
A4: MU | B4: 1100031 | C4: Cabixi (RO) | D4: 5351 | E4: Pessoas
A5: MU | B5: 1100049 | C5: Cacoal (RO) | D5: 86887 | E5: Pessoas
A6: MU | B6: 1100056 | C6: Cerejeiras (RO) | D6: 15890 | E6: Pessoas
A7: MU | B7: 1100064 | C7: Colorado do Oeste (RO) | D7: 15663 | E7: Pessoas
A8: MU | B8: 1100072 | C8: Corumbiara (RO) | D8: 7519 | E8: Pessoas
A9: MU | B9: 1100080 | C9: Costa Marques (RO) | D9: 12627 | E9: Pessoas
A10: MU | B10: 1100098 | C10: Espigão D'Oeste (RO) | D10: 29414 | E10: Pessoas
A11: MU | B11: 1100106 | C11: Guajará-Mirim (RO) | D11: 39387 | E11: Pessoas
A12: MU | B12: 1100114 | C12: Jaru (RO) | D12: 50591 | E12: Pessoas
A13: MU | B13: 1100122 | C13: Ji-Paraná (RO) | D13: 124333 | E13: Pessoas
... A16711: MU | B16711: 5300108 | C16711: Brasília (DF) | D16711: 489.06 | E16711: Habitante por quilômetro quadrado

Sheet Tabela Dinâmica Tabela 4714
A3: Soma de Quantidade | C3: Dado
A4: Cód. | B4: Município | C4: Habitante por quilômetro quadrado | D4: Pessoas | E4: Quilômetros quadrados
A5: 1100015 | B5: Alta Floresta D'Oeste (RO) | C5: 3.04 | D5: 21494 | E5: 7067.127
A6: 1100023 | B6: Ariquemes (RO) | C6: 21.88 | D6: 96833 | E6: 4426.571
A7: 1100031 | B7: Cabixi (RO) | C7: 4.07 | D7: 5351 | E7: 1314.352
A8: 1100049 | B8: Cacoal (RO) | C8: 22.91 | D8: 86887 | E8: 3793
A9: 1100056 | B9: Cerejeiras (RO) | C9: 5.71 | D9: 15890 | E9: 2783.3
A10: 1100064 | B10: Colorado do Oeste (RO) | C10: 10.79 | D10: 15663 | E10: 1451.06
A11: 1100072 | B11: Corumbiara (RO) | C11: 2.46 | D11: 7519 | E11: 3060.321
A12: 1100080 | B12: Costa Marques (RO) | C12: 2.53 | D12: 12627 | E12: 4987.177
A13: 1100098 | B13: Espigão D'Oeste (RO) | C13: 6.51 | D13: 29414 | E13: 4518.038
A14: 1100106 | B14: Guajará-Mirim (RO) | C14: 1.58 | D14: 39387 | E14: 24856.877
A15: 1100114 | B15: Jaru (RO) | C15: 17.18 | D15: 50591 | E15: 2944.128
A16: 1100122 | B16: Ji-Paraná (RO) | C16: 18.03 | D16: 124333 | E16: 6896.649
... A5574: 5300108 | B5574: Brasília (DF) | C5574: 489.06 | D5574: 2817381 | E5574: 5760.784
A5575: Total Geral | C5575: 646134.27 | D5575: 203080756 | E5575: 8497331.9

Sheet Tabela 4714 Tratada
A1: Cód. | B1: Município | C1: Habitante por quilômetro quadrado | D1: Pessoas | E1: Quilômetros quadrados
A2: 1100015 | B2: Alta Floresta D'Oeste (RO) | C2: 3.04 | D2: 21494 | E2: 7067.127
A3: 1100023 | B3: Ariquemes (RO) | C3: 21.88 | D3: 96833 | E3: 4426.571
A4: 1100031 | B4: Cabixi (RO) | C4: 4.07 | D4: 5351 | E4: 1314.352
A5: 1100049 | B5: Cacoal (RO) | C5: 22.91 | D5: 86887 | E5: 3793
A6: 1100056 | B6: Cerejeiras (RO) | C6: 5.71 | D6: 15890 | E6: 2783.3
A7: 1100064 | B7: Colorado do Oeste (RO) | C7: 10.79 | D7: 15663 | E7: 1451.06
A8: 1100072 | B8: Corumbiara (RO) | C8: 2.46 | D8: 7519 | E8: 3060.321
A9: 1100080 | B9: Costa Marques (RO) | C9: 2.53 | D9: 12627 | E9: 4987.177
A10: 1100098 | B10: Espigão D'Oeste (RO) | C10: 6.51 | D10: 29414 | E10: 4518.038
A11: 1100106 | B11: Guajará-Mirim (RO) | C11: 1.58 | D11: 39387 | E11: 24856.877
A12: 1100114 | B12: Jaru (RO) | C12: 17.18 | D12: 50591 | E12: 2944.128
A13: 1100122 | B13: Ji-Paraná (RO) | C13: 18.03 | D13: 124333 | E13: 6896.649
... A1101: 2402204 | B1101: Canguaretama (RN) | C1101: 120.85 | D1101: 29668 | E1101: 245.485
A1102: 2402303 | B1102: Caraúbas (RN) | C1102: 18 | D1102: 19727 | E1102: 1095.803
A1103: 2402402 | B1103: Carnaúba dos Dantas (RN) | C1103: 32.45 | D1103: 7992 | E1103: 246.308
A1104: 2402501 | B1104: Carnaubais (RN) | C1104: 18.76 | D1104: 9714 | E1104: 517.737
A1105: 2402600 | B1105: Ceará-Mirim (RN) | C1105: 109.15 | D1105: 79115 | E1105: 724.838
A1106: 2402709 | B1106: Cerro Corá (RN) | C1106: 27.95 | D1106: 11000 | E1106: 393.573
A1107: 2402808 | B1107: Coronel Ezequiel (RN) | C1107: 27.55 | D1107: 5117 | E1107: 185.748
A1108: 2402907 | B1108: Coronel João Pessoa (RN) | C1108: 36.17 | D1108: 4237 | E1108: 117.139
A1109: 2403004 | B1109: Cruzeta (RN) | C1109: 27.06 | D1109: 8005 | E1109: 295.83
A1110: 2403103 | B1110: Currais Novos (RN) | C1110: 47.8 | D1110: 41313 | E1110: 864.349
A1111: 2403202 | B1111: Doutor Severiano (RN) | C1111: 61.93 | D1111: 7044 | E1111: 113.737
A1112: 2403251 | B1112: Parnamirim (RN) | C1112: 2037.93 | D1112: 252716 | E1112: 124.006
A1113: 2403301 | B1113: Encanto (RN) | C1113: 47.84 | D1113: 6016 | E1113: 125.749
A1114: 2403400 | B1114: Equador (RN) | C1114: 20.23 | D1114: 5360 | E1114: 264.985
... A5571: 5300108 | B5571: Brasília (DF) | C5571: 489.06 | D5571: 2817381 | E5571: 5760.784
A5572: Total Geral | C5572: 646134.27 | D5572: 203080756 | E5572: 8497331.9

Sheet Base de Dados Amostral
A1: codigo_municipio_completo | B1: codigo_uf | C1: nome_uf | D1: codigo_municipio | E1: nome_municipio | F1: regiao | G1: url | H1: site_encontrado | I1: url_confiavel | J1: status_validacao_url | K1: observacao | L1: populacao_residente_2022 | M1: area_territorial_km2 | N1: densidade_demografica_hab_km2 | O1: chave_aleatoria
A2: ='Amostra Sorteada'!C2 -> 5107909 | B2: ='Amostra Sorteada'!A2 -> 51 | C2: ='Amostra Sorteada'!B2 -> Mato Grosso | D2: ='Amostra Sorteada'!D2 -> 07909 | E2: ='Amostra Sorteada'!E2 -> Sinop | F2: ='Amostra Sorteada'!F2 -> Centro-Oeste | G2: ='Amostra Sorteada'!L2 -> https://www.sinop.mt.gov.br/ | H2: ='Amostra Sorteada'!I2 -> Sim | I2: ='Amostra Sorteada'!J2 -> Sim | J2: ='Amostra Sorteada'!K2 -> Apto | K2: ='Amostra Sorteada'!M2 -> 0 | L2: =_xlfn.XLOOKUP($A2,'Tabela 4714 Tratada'!$A:$A,'Tabela 4714 Tratada'!$D:$D,"Não encontrado") -> 196312 | M2: =_xlfn.XLOOKUP($A2,'Tabela 4714 Tratada'!$A:$A,'Tabela 4714 Tratada'!$E:$E,"Não encontrado") -> 3990.87 | N2: =_xlfn.XLOOKUP($A2,'Tabela 4714 Tratada'!$A:$A,'Tabela 4714 Tratada'!$C:$C,"Não encontrado") -> 49.19 | O2: ='Amostra Sorteada'!G2 -> 0.0025088861
A3: ='Amostra Sorteada'!C3 -> 5108402 | B3: ='Amostra Sorteada'!A3 -> 51 | C3: ='Amostra Sorteada'!B3 -> Mato Grosso | D3: ='Amostra Sorteada'!D3 -> 08402 | E3: ='Amostra Sorteada'!E3 -> Várzea Grande | F3: ='Amostra Sorteada'!F3 -> Centro-Oeste | G3: ='Amostra Sorteada'!L3 -> https://www.varzeagrande.mt.gov.br/ | H3: ='Amostra Sorteada'!I3 -> Sim | I3: ='Amostra Sorteada'!J3 -> Sim | J3: ='Amostra Sorteada'!K3 -> Apto | K3: ='Amostra Sorteada'!M3 -> 0 | L3: =_xlfn.XLOOKUP($A3,'Tabela 4714 Tratada'!$A:$A,'Tabela 4714 Tratada'!$D:$D,"Não encontrado") -> 300078 | M3: =_xlfn.XLOOKUP($A3,'Tabela 4714 Tratada'!$A:$A,'Tabela 4714 Tratada'!$E:$E,"Não encontrado") -> 724.279 | N3: =_xlfn.XLOOKUP($A3,'Tabela 4714 Tratada'!$A:$A,'Tabela 4714 Tratada'!$C:$C,"Não encontrado") -> 414.31 | O3: ='Amostra Sorteada'!G3 -> 0.0042295342
A4: ='Amostra Sorteada'!C4 -> 5206602 | B4: ='Amostra Sorteada'!A4 -> 52 | C4: ='Amostra Sorteada'!B4 -> Goiás | D4: ='Amostra Sorteada'!D4 -> 06602 | E4: ='Amostra Sorteada'!E4 -> Cumari | F4: ='Amostra Sorteada'!F4 -> Centro-Oeste | G4: ='Amostra Sorteada'!L4 -> https://cumari.go.gov.br/ | H4: ='Amostra Sorteada'!I4 -> Sim | I4: ='Amostra Sorteada'!J4 -> Sim | J4: ='Amostra Sorteada'!K4 -> Apto | K4: ='Amostra Sorteada'!M4 -> 0 | L4: =_xlfn.XLOOKUP($A4,'Tabela 4714 Tratada'!$A:$A,'Tabela 4714 Tratada'!$D:$D,"Não encontrado") -> 2927 | M4: =_xlfn.XLOOKUP($A4,'Tabela 4714 Tratada'!$A:$A,'Tabela 4714 Tratada'!$E:$E,"Não encontrado") -> 568.365 | N4: =_xlfn.XLOOKUP($A4,'Tabela 4714 Tratada'!$A:$A,'Tabela 4714 Tratada'!$C:$C,"Não encontrado") -> 5.15 | O4: ='Amostra Sorteada'!G4 -> 0.005838812
A5: ='Amostra Sorteada'!C5 -> 5220454 | B5: ='Amostra Sorteada'!A5 -> 52 | C5: ='Amostra Sorteada'!B5 -> Goiás | D5: ='Amostra Sorteada'!D5 -> 20454 | E5: ='Amostra Sorteada'!E5 -> Senador Canedo | F5: ='Amostra Sorteada'!F5 -> Centro-Oeste | G5: ='Amostra Sorteada'!L5 -> https://senadorcanedo.go.gov.br/ | H5: ='Amostra Sorteada'!I5 -> Sim | I5: ='Amostra Sorteada'!J5 -> Sim | J5: ='Amostra Sorteada'!K5 -> Apto | K5: ='Amostra Sorteada'!M5 -> 0 | L5: =_xlfn.XLOOKUP($A5,'Tabela 4714 Tratada'!$A:$A,'Tabela 4714 Tratada'!$D:$D,"Não encontrado") -> 155635 | M5: =_xlfn.XLOOKUP($A5,'Tabela 4714 Tratada'!$A:$A,'Tabela 4714 Tratada'!$E:$E,"Não encontrado") -> 247.005 | N5: =_xlfn.XLOOKUP($A5,'Tabela 4714 Tratada'!$A:$A,'Tabela 4714 Tratada'!$C:$C,"Não encontrado") -> 630.09 | O5: ='Amostra Sorteada'!G5 -> 0.0062921544
A6: ='Amostra Sorteada'!C6 -> 5207253 | B6: ='Amostra Sorteada'!A6 -> 52 | C6: ='Amostra Sorteada'!B6 -> Goiás | D6: ='Amostra Sorteada'!D6 -> 07253 | E6: ='Amostra Sorteada'!E6 -> Doverlândia | F6: ='Amostra Sorteada'!F6 -> Centro-Oeste | G6: ='Amostra Sorteada'!L6 -> https://doverlandia.go.gov.br/ | H6: ='Amostra Sorteada'!I6 -> Sim | I6: ='Amostra Sorteada'!J6 -> Sim | J6: ='Amostra Sorteada'!K6 -> Apto | K6: ='Amostra Sorteada'!M6 -> 0 | L6: =_xlfn.XLOOKUP($A6,'Tabela 4714 Tratada'!$A:$A,'Tabela 4714 Tratada'!$D:$D,"Não encontrado") -> 6956 | M6: =_xlfn.XLOOKUP($A6,'Tabela 4714 Tratada'!$A:$A,'Tabela 4714 Tratada'!$E:$E,"Não encontrado") -> 3227.558 | N6: =_xlfn.XLOOKUP($A6,'Tabela 4714 Tratada'!$A:$A,'Tabela 4714 Tratada'!$C:$C,"Não encontrado") -> 2.16 | O6: ='Amostra Sorteada'!G6 -> 0.0064175894
A7: ='Amostra Sorteada'!C7 -> 5103437 | B7: ='Amostra Sorteada'!A7 -> 51 | C7: ='Amostra Sorteada'!B7 -> Mato Grosso | D7: ='Amostra Sorteada'!D7 -> 03437 | E7: ='Amostra Sorteada'!E7 -> Curvelândia | F7: ='Amostra Sorteada'!F7 -> Centro-Oeste | G7: ='Amostra Sorteada'!L7 -> https://www.curvelandia.mt.gov.br/ | H7: ='Amostra Sorteada'!I7 -> Sim | I7: ='Amostra Sorteada'!J7 -> Sim | J7: ='Amostra Sorteada'!K7 -> Apto | K7: ='Amostra Sorteada'!M7 -> 0 | L7: =_xlfn.XLOOKUP($A7,'Tabela 4714 Tratada'!$A:$A,'Tabela 4714 Tratada'!$D:$D,"Não encontrado") -> 4903 | M7: =_xlfn.XLOOKUP($A7,'Tabela 4714 Tratada'!$A:$A,'Tabela 4714 Tratada'!$E:$E,"Não encontrado") -> 357.128 | N7: =_xlfn.XLOOKUP($A7,'Tabela 4714 Tratada'!$A:$A,'Tabela 4714 Tratada'!$C:$C,"Não encontrado") -> 13.73 | O7: ='Amostra Sorteada'!G7 -> 0.0065792411
A8: ='Amostra Sorteada'!C8 -> 5204656 | B8: ='Amostra Sorteada'!A8 -> 52 | C8: ='Amostra Sorteada'!B8 -> Goiás | D8: ='Amostra Sorteada'!D8 -> 04656 | E8: ='Amostra Sorteada'!E8 -> Campinaçu | F8: ='Amostra Sorteada'!F8 -> Centro-Oeste | G8: ='Amostra Sorteada'!L8 -> https://www.campinacu.go.gov.br/ | H8: ='Amostra Sorteada'!I8 -> Sim | I8: ='Amostra Sorteada'!J8 -> Sim | J8: ='Amostra Sorteada'!K8 -> Apto | K8: ='Amostra Sorteada'!M8 -> 0 | L8: =_xlfn.XLOOKUP($A8,'Tabela 4714 Tratada'!$A:$A,'Tabela 4714 Tratada'!$D:$D,"Não encontrado") -> 3708 | M8: =_xlfn.XLOOKUP($A8,'Tabela 4714 Tratada'!$A:$A,'Tabela 4714 Tratada'!$E:$E,"Não encontrado") -> 1978.386 | N8: =_xlfn.XLOOKUP($A8,'Tabela 4714 Tratada'!$A:$A,'Tabela 4714 Tratada'!$C:$C,"Não encontrado") -> 1.87 | O8: ='Amostra Sorteada'!G8 -> 0.008315084
A9: ='Amostra Sorteada'!C9 -> 5213905 | B9: ='Amostra Sorteada'!A9 -> 52 | C9: ='Amostra Sorteada'!B9 -> Goiás | D9: ='Amostra Sorteada'!D9 -> 13905 | E9: ='Amostra Sorteada'!E9 -> Mossâmedes | F9: ='Amostra Sorteada'!F9 -> Centro-Oeste | G9: ='Amostra Sorteada'!L9 -> http://mossamedes.go.gov.br/ | H9: ='Amostra Sorteada'!I9 -> Sim | I9: ='Amostra Sorteada'!J9 -> Sim | J9: ='Amostra Sorteada'!K9 -> Apto | K9: ='Amostra Sorteada'!M9 -> 0 | L9: =_xlfn.XLOOKUP($A9,'Tabela 4714 Tratada'!$A:$A,'Tabela 4714 Tratada'!$D:$D,"Não encontrado") -> 4654 | M9: =_xlfn.XLOOKUP($A9,'Tabela 4714 Tratada'!$A:$A,'Tabela 4714 Tratada'!$E:$E,"Não encontrado") -> 684.882 | N9: =_xlfn.XLOOKUP($A9,'Tabela 4714 Tratada'!$A:$A,'Tabela 4714 Tratada'!$C:$C,"Não encontrado") -> 6.8 | O9: ='Amostra Sorteada'!G9 -> 0.010133321
A10: ='Amostra Sorteada'!C10 -> 5002704 | B10: ='Amostra Sorteada'!A10 -> 50 | C10: ='Amostra Sorteada'!B10 -> Mato Grosso do Sul | D10: ='Amostra Sorteada'!D10 -> 02704 | E10: ='Amostra Sorteada'!E10 -> Campo Grande | F10: ='Amostra Sorteada'!F10 -> Centro-Oeste | G10: ='Amostra Sorteada'!L10 -> https://www.campogrande.ms.gov.br/ | H10: ='Amostra Sorteada'!I10 -> Sim | I10: ='Amostra Sorteada'!J10 -> Sim | J10: ='Amostra Sorteada'!K10 -> Apto | K10: ='Amostra Sorteada'!M10 -> 0 | L10: =_xlfn.XLOOKUP($A10,'Tabela 4714 Tratada'!$A:$A,'Tabela 4714 Tratada'!$D:$D,"Não encontrado") -> 898100 | M10: =_xlfn.XLOOKUP($A10,'Tabela 4714 Tratada'!$A:$A,'Tabela 4714 Tratada'!$E:$E,"Não encontrado") -> 8082.978 | N10: =_xlfn.XLOOKUP($A10,'Tabela 4714 Tratada'!$A:$A,'Tabela 4714 Tratada'!$C:$C,"Não encontrado") -> 111.11 | O10: ='Amostra Sorteada'!G10 -> 0.011278
A11: ='Amostra Sorteada'!C11 -> 5210802 | B11: ='Amostra Sorteada'!A11 -> 52 | C11: ='Amostra Sorteada'!B11 -> Goiás | D11: ='Amostra Sorteada'!D11 -> 10802 | E11: ='Amostra Sorteada'!E11 -> Itajá | F11: ='Amostra Sorteada'!F11 -> Centro-Oeste | G11: ='Amostra Sorteada'!L11 -> https://itaja.go.gov.br/ | H11: ='Amostra Sorteada'!I11 -> Sim | I11: ='Amostra Sorteada'!J11 -> Sim | J11: ='Amostra Sorteada'!K11 -> Apto | K11: ='Amostra Sorteada'!M11 -> 0 | L11: =_xlfn.XLOOKUP($A11,'Tabela 4714 Tratada'!$A:$A,'Tabela 4714 Tratada'!$D:$D,"Não encontrado") -> 4380 | M11: =_xlfn.XLOOKUP($A11,'Tabela 4714 Tratada'!$A:$A,'Tabela 4714 Tratada'!$E:$E,"Não encontrado") -> 2082.736 | N11: =_xlfn.XLOOKUP($A11,'Tabela 4714 Tratada'!$A:$A,'Tabela 4714 Tratada'!$C:$C,"Não encontrado") -> 2.1 | O11: ='Amostra Sorteada'!G11 -> 0.012106377
A12: ='Amostra Sorteada'!C12 -> 5007208 | B12: ='Amostra Sorteada'!A12 -> 50 | C12: ='Amostra Sorteada'!B12 -> Mato Grosso do Sul | D12: ='Amostra Sorteada'!D12 -> 07208 | E12: ='Amostra Sorteada'!E12 -> Rio Brilhante | F12: ='Amostra Sorteada'!F12 -> Centro-Oeste | G12: ='Amostra Sorteada'!L12 -> https://riobrilhante.ms.gov.br/ | H12: ='Amostra Sorteada'!I12 -> Sim | I12: ='Amostra Sorteada'!J12 -> Sim | J12: ='Amostra Sorteada'!K12 -> Apto | K12: ='Amostra Sorteada'!M12 -> 0 | L12: =_xlfn.XLOOKUP($A12,'Tabela 4714 Tratada'!$A:$A,'Tabela 4714 Tratada'!$D:$D,"Não encontrado") -> 37601 | M12: =_xlfn.XLOOKUP($A12,'Tabela 4714 Tratada'!$A:$A,'Tabela 4714 Tratada'!$E:$E,"Não encontrado") -> 3983.562 | N12: =_xlfn.XLOOKUP($A12,'Tabela 4714 Tratada'!$A:$A,'Tabela 4714 Tratada'!$C:$C,"Não encontrado") -> 9.44 | O12: ='Amostra Sorteada'!G12 -> 0.015918488
A13: ='Amostra Sorteada'!C13 -> 5214838 | B13: ='Amostra Sorteada'!A13 -> 52 | C13: ='Amostra Sorteada'!B13 -> Goiás | D13: ='Amostra Sorteada'!D13 -> 14838 | E13: ='Amostra Sorteada'!E13 -> Nova Crixás | F13: ='Amostra Sorteada'!F13 -> Centro-Oeste | G13: ='Amostra Sorteada'!L13 -> https://novacrixas.go.gov.br/ | H13: ='Amostra Sorteada'!I13 -> Sim | I13: ='Amostra Sorteada'!J13 -> Sim | J13: ='Amostra Sorteada'!K13 -> Apto | K13: ='Amostra Sorteada'!M13 -> 0 | L13: =_xlfn.XLOOKUP($A13,'Tabela 4714 Tratada'!$A:$A,'Tabela 4714 Tratada'!$D:$D,"Não encontrado") -> 12815 | M13: =_xlfn.XLOOKUP($A13,'Tabela 4714 Tratada'!$A:$A,'Tabela 4714 Tratada'!$E:$E,"Não encontrado") -> 7308.681 | N13: =_xlfn.XLOOKUP($A13,'Tabela 4714 Tratada'!$A:$A,'Tabela 4714 Tratada'!$C:$C,"Não encontrado") -> 1.75 | O13: ='Amostra Sorteada'!G13 -> 0.016464116
... A389: ='Amostra Sorteada'!C389 -> 4300570 | B389: ='Amostra Sorteada'!A389 -> 43 | C389: ='Amostra Sorteada'!B389 -> Rio Grande do Sul | D389: ='Amostra Sorteada'!D389 -> 00570 | E389: ='Amostra Sorteada'!E389 -> Alto Feliz | F389: ='Amostra Sorteada'!F389 -> Sul | G389: ='Amostra Sorteada'!L389 -> https://www.altofeliz.rs.gov.br/web/ | H389: ='Amostra Sorteada'!I389 -> Sim | I389: ='Amostra Sorteada'!J389 -> Sim | J389: ='Amostra Sorteada'!K389 -> Apto | K389: ='Amostra Sorteada'!M389 -> 0 | L389: =_xlfn.XLOOKUP($A389,'Tabela 4714 Tratada'!$A:$A,'Tabela 4714 Tratada'!$D:$D,"Não encontrado") -> 3072 | M389: =_xlfn.XLOOKUP($A389,'Tabela 4714 Tratada'!$A:$A,'Tabela 4714 Tratada'!$E:$E,"Não encontrado") -> 78.175 | N389: =_xlfn.XLOOKUP($A389,'Tabela 4714 Tratada'!$A:$A,'Tabela 4714 Tratada'!$C:$C,"Não encontrado") -> 39.3 | O389: ='Amostra Sorteada'!G389 -> 0.06913189

Sheet Base de Amostras Descartadas
A1: codigo_municipio_completo | B1: codigo_uf | C1: nome_uf | D1: codigo_municipio | E1: nome_municipio | F1: regiao | G1: url | H1: site_encontrado | I1: url_confiavel | J1: status_validacao_url | K1: observacao | L1: populacao_residente_2022 | M1: area_territorial_km2 | N1: densidade_demografica_hab_km2 | O1: chave_aleatoria
A2: ='Amostra Sorteada'!C2 -> 5107909 | B2: ='Amostra Sorteada'!A2 -> 51 | C2: ='Amostra Sorteada'!B2 -> Mato Grosso | D2: ='Amostra Sorteada'!D2 -> 07909 | E2: ='Amostra Sorteada'!E2 -> Sinop | F2: ='Amostra Sorteada'!F2 -> Centro-Oeste | G2: ='Amostra Sorteada'!L2 -> https://www.sinop.mt.gov.br/ | H2: ='Amostra Sorteada'!I2 -> Sim | I2: ='Amostra Sorteada'!J2 -> Sim | J2: ='Amostra Sorteada'!K2 -> Apto | K2: ='Amostra Sorteada'!M2 -> 0 | L2: =_xlfn.XLOOKUP($A2,'Tabela 4714 Tratada'!$A:$A,'Tabela 4714 Tratada'!$D:$D,"Não encontrado") -> 196312 | M2: =_xlfn.XLOOKUP($A2,'Tabela 4714 Tratada'!$A:$A,'Tabela 4714 Tratada'!$E:$E,"Não encontrado") -> 3990.87 | N2: =_xlfn.XLOOKUP($A2,'Tabela 4714 Tratada'!$A:$A,'Tabela 4714 Tratada'!$C:$C,"Não encontrado") -> 49.19 | O2: ='Amostra Sorteada'!G2 -> 0.0025088861
A3: ='Amostra Sorteada'!C3 -> 5108402 | B3: ='Amostra Sorteada'!A3 -> 51 | C3: ='Amostra Sorteada'!B3 -> Mato Grosso | D3: ='Amostra Sorteada'!D3 -> 08402 | E3: ='Amostra Sorteada'!E3 -> Várzea Grande | F3: ='Amostra Sorteada'!F3 -> Centro-Oeste | G3: ='Amostra Sorteada'!L3 -> https://www.varzeagrande.mt.gov.br/ | H3: ='Amostra Sorteada'!I3 -> Sim | I3: ='Amostra Sorteada'!J3 -> Sim | J3: ='Amostra Sorteada'!K3 -> Apto | K3: ='Amostra Sorteada'!M3 -> 0 | L3: =_xlfn.XLOOKUP($A3,'Tabela 4714 Tratada'!$A:$A,'Tabela 4714 Tratada'!$D:$D,"Não encontrado") -> 300078 | M3: =_xlfn.XLOOKUP($A3,'Tabela 4714 Tratada'!$A:$A,'Tabela 4714 Tratada'!$E:$E,"Não encontrado") -> 724.279 | N3: =_xlfn.XLOOKUP($A3,'Tabela 4714 Tratada'!$A:$A,'Tabela 4714 Tratada'!$C:$C,"Não encontrado") -> 414.31 | O3: ='Amostra Sorteada'!G3 -> 0.0042295342
A4: ='Amostra Sorteada'!C4 -> 5206602 | B4: ='Amostra Sorteada'!A4 -> 52 | C4: ='Amostra Sorteada'!B4 -> Goiás | D4: ='Amostra Sorteada'!D4 -> 06602 | E4: ='Amostra Sorteada'!E4 -> Cumari | F4: ='Amostra Sorteada'!F4 -> Centro-Oeste | G4: ='Amostra Sorteada'!L4 -> https://cumari.go.gov.br/ | H4: ='Amostra Sorteada'!I4 -> Sim | I4: ='Amostra Sorteada'!J4 -> Sim | J4: ='Amostra Sorteada'!K4 -> Apto | K4: ='Amostra Sorteada'!M4 -> 0 | L4: =_xlfn.XLOOKUP($A4,'Tabela 4714 Tratada'!$A:$A,'Tabela 4714 Tratada'!$D:$D,"Não encontrado") -> 2927 | M4: =_xlfn.XLOOKUP($A4,'Tabela 4714 Tratada'!$A:$A,'Tabela 4714 Tratada'!$E:$E,"Não encontrado") -> 568.365 | N4: =_xlfn.XLOOKUP($A4,'Tabela 4714 Tratada'!$A:$A,'Tabela 4714 Tratada'!$C:$C,"Não encontrado") -> 5.15 | O4: ='Amostra Sorteada'!G4 -> 0.005838812
A5: ='Amostra Sorteada'!C5 -> 5220454 | B5: ='Amostra Sorteada'!A5 -> 52 | C5: ='Amostra Sorteada'!B5 -> Goiás | D5: ='Amostra Sorteada'!D5 -> 20454 | E5: ='Amostra Sorteada'!E5 -> Senador Canedo | F5: ='Amostra Sorteada'!F5 -> Centro-Oeste | G5: ='Amostra Sorteada'!L5 -> https://senadorcanedo.go.gov.br/ | H5: ='Amostra Sorteada'!I5 -> Sim | I5: ='Amostra Sorteada'!J5 -> Sim | J5: ='Amostra Sorteada'!K5 -> Apto | K5: ='Amostra Sorteada'!M5 -> 0 | L5: =_xlfn.XLOOKUP($A5,'Tabela 4714 Tratada'!$A:$A,'Tabela 4714 Tratada'!$D:$D,"Não encontrado") -> 155635 | M5: =_xlfn.XLOOKUP($A5,'Tabela 4714 Tratada'!$A:$A,'Tabela 4714 Tratada'!$E:$E,"Não encontrado") -> 247.005 | N5: =_xlfn.XLOOKUP($A5,'Tabela 4714 Tratada'!$A:$A,'Tabela 4714 Tratada'!$C:$C,"Não encontrado") -> 630.09 | O5: ='Amostra Sorteada'!G5 -> 0.0062921544
A6: ='Amostra Sorteada'!C6 -> 5207253 | B6: ='Amostra Sorteada'!A6 -> 52 | C6: ='Amostra Sorteada'!B6 -> Goiás | D6: ='Amostra Sorteada'!D6 -> 07253 | E6: ='Amostra Sorteada'!E6 -> Doverlândia | F6: ='Amostra Sorteada'!F6 -> Centro-Oeste | G6: ='Amostra Sorteada'!L6 -> https://doverlandia.go.gov.br/ | H6: ='Amostra Sorteada'!I6 -> Sim | I6: ='Amostra Sorteada'!J6 -> Sim | J6: ='Amostra Sorteada'!K6 -> Apto | K6: ='Amostra Sorteada'!M6 -> 0 | L6: =_xlfn.XLOOKUP($A6,'Tabela 4714 Tratada'!$A:$A,'Tabela 4714 Tratada'!$D:$D,"Não encontrado") -> 6956 | M6: =_xlfn.XLOOKUP($A6,'Tabela 4714 Tratada'!$A:$A,'Tabela 4714 Tratada'!$E:$E,"Não encontrado") -> 3227.558 | N6: =_xlfn.XLOOKUP($A6,'Tabela 4714 Tratada'!$A:$A,'Tabela 4714 Tratada'!$C:$C,"Não encontrado") -> 2.16 | O6: ='Amostra Sorteada'!G6 -> 0.0064175894
A7: ='Amostra Sorteada'!C7 -> 5103437 | B7: ='Amostra Sorteada'!A7 -> 51 | C7: ='Amostra Sorteada'!B7 -> Mato Grosso | D7: ='Amostra Sorteada'!D7 -> 03437 | E7: ='Amostra Sorteada'!E7 -> Curvelândia | F7: ='Amostra Sorteada'!F7 -> Centro-Oeste | G7: ='Amostra Sorteada'!L7 -> https://www.curvelandia.mt.gov.br/ | H7: ='Amostra Sorteada'!I7 -> Sim | I7: ='Amostra Sorteada'!J7 -> Sim | J7: ='Amostra Sorteada'!K7 -> Apto | K7: ='Amostra Sorteada'!M7 -> 0 | L7: =_xlfn.XLOOKUP($A7,'Tabela 4714 Tratada'!$A:$A,'Tabela 4714 Tratada'!$D:$D,"Não encontrado") -> 4903 | M7: =_xlfn.XLOOKUP($A7,'Tabela 4714 Tratada'!$A:$A,'Tabela 4714 Tratada'!$E:$E,"Não encontrado") -> 357.128 | N7: =_xlfn.XLOOKUP($A7,'Tabela 4714 Tratada'!$A:$A,'Tabela 4714 Tratada'!$C:$C,"Não encontrado") -> 13.73 | O7: ='Amostra Sorteada'!G7 -> 0.0065792411
A8: ='Amostra Sorteada'!C8 -> 5204656 | B8: ='Amostra Sorteada'!A8 -> 52 | C8: ='Amostra Sorteada'!B8 -> Goiás | D8: ='Amostra Sorteada'!D8 -> 04656 | E8: ='Amostra Sorteada'!E8 -> Campinaçu | F8: ='Amostra Sorteada'!F8 -> Centro-Oeste | G8: ='Amostra Sorteada'!L8 -> https://www.campinacu.go.gov.br/ | H8: ='Amostra Sorteada'!I8 -> Sim | I8: ='Amostra Sorteada'!J8 -> Sim | J8: ='Amostra Sorteada'!K8 -> Apto | K8: ='Amostra Sorteada'!M8 -> 0 | L8: =_xlfn.XLOOKUP($A8,'Tabela 4714 Tratada'!$A:$A,'Tabela 4714 Tratada'!$D:$D,"Não encontrado") -> 3708 | M8: =_xlfn.XLOOKUP($A8,'Tabela 4714 Tratada'!$A:$A,'Tabela 4714 Tratada'!$E:$E,"Não encontrado") -> 1978.386 | N8: =_xlfn.XLOOKUP($A8,'Tabela 4714 Tratada'!$A:$A,'Tabela 4714 Tratada'!$C:$C,"Não encontrado") -> 1.87 | O8: ='Amostra Sorteada'!G8 -> 0.008315084
A9: ='Amostra Sorteada'!C9 -> 5213905 | B9: ='Amostra Sorteada'!A9 -> 52 | C9: ='Amostra Sorteada'!B9 -> Goiás | D9: ='Amostra Sorteada'!D9 -> 13905 | E9: ='Amostra Sorteada'!E9 -> Mossâmedes | F9: ='Amostra Sorteada'!F9 -> Centro-Oeste | G9: ='Amostra Sorteada'!L9 -> http://mossamedes.go.gov.br/ | H9: ='Amostra Sorteada'!I9 -> Sim | I9: ='Amostra Sorteada'!J9 -> Sim | J9: ='Amostra Sorteada'!K9 -> Apto | K9: ='Amostra Sorteada'!M9 -> 0 | L9: =_xlfn.XLOOKUP($A9,'Tabela 4714 Tratada'!$A:$A,'Tabela 4714 Tratada'!$D:$D,"Não encontrado") -> 4654 | M9: =_xlfn.XLOOKUP($A9,'Tabela 4714 Tratada'!$A:$A,'Tabela 4714 Tratada'!$E:$E,"Não encontrado") -> 684.882 | N9: =_xlfn.XLOOKUP($A9,'Tabela 4714 Tratada'!$A:$A,'Tabela 4714 Tratada'!$C:$C,"Não encontrado") -> 6.8 | O9: ='Amostra Sorteada'!G9 -> 0.010133321
A10: ='Amostra Sorteada'!C10 -> 5002704 | B10: ='Amostra Sorteada'!A10 -> 50 | C10: ='Amostra Sorteada'!B10 -> Mato Grosso do Sul | D10: ='Amostra Sorteada'!D10 -> 02704 | E10: ='Amostra Sorteada'!E10 -> Campo Grande | F10: ='Amostra Sorteada'!F10 -> Centro-Oeste | G10: ='Amostra Sorteada'!L10 -> https://www.campogrande.ms.gov.br/ | H10: ='Amostra Sorteada'!I10 -> Sim | I10: ='Amostra Sorteada'!J10 -> Sim | J10: ='Amostra Sorteada'!K10 -> Apto | K10: ='Amostra Sorteada'!M10 -> 0 | L10: =_xlfn.XLOOKUP($A10,'Tabela 4714 Tratada'!$A:$A,'Tabela 4714 Tratada'!$D:$D,"Não encontrado") -> 898100 | M10: =_xlfn.XLOOKUP($A10,'Tabela 4714 Tratada'!$A:$A,'Tabela 4714 Tratada'!$E:$E,"Não encontrado") -> 8082.978 | N10: =_xlfn.XLOOKUP($A10,'Tabela 4714 Tratada'!$A:$A,'Tabela 4714 Tratada'!$C:$C,"Não encontrado") -> 111.11 | O10: ='Amostra Sorteada'!G10 -> 0.011278
A11: ='Amostra Sorteada'!C11 -> 5210802 | B11: ='Amostra Sorteada'!A11 -> 52 | C11: ='Amostra Sorteada'!B11 -> Goiás | D11: ='Amostra Sorteada'!D11 -> 10802 | E11: ='Amostra Sorteada'!E11 -> Itajá | F11: ='Amostra Sorteada'!F11 -> Centro-Oeste | G11: ='Amostra Sorteada'!L11 -> https://itaja.go.gov.br/ | H11: ='Amostra Sorteada'!I11 -> Sim | I11: ='Amostra Sorteada'!J11 -> Sim | J11: ='Amostra Sorteada'!K11 -> Apto | K11: ='Amostra Sorteada'!M11 -> 0 | L11: =_xlfn.XLOOKUP($A11,'Tabela 4714 Tratada'!$A:$A,'Tabela 4714 Tratada'!$D:$D,"Não encontrado") -> 4380 | M11: =_xlfn.XLOOKUP($A11,'Tabela 4714 Tratada'!$A:$A,'Tabela 4714 Tratada'!$E:$E,"Não encontrado") -> 2082.736 | N11: =_xlfn.XLOOKUP($A11,'Tabela 4714 Tratada'!$A:$A,'Tabela 4714 Tratada'!$C:$C,"Não encontrado") -> 2.1 | O11: ='Amostra Sorteada'!G11 -> 0.012106377
A12: ='Amostra Sorteada'!C12 -> 5007208 | B12: ='Amostra Sorteada'!A12 -> 50 | C12: ='Amostra Sorteada'!B12 -> Mato Grosso do Sul | D12: ='Amostra Sorteada'!D12 -> 07208 | E12: ='Amostra Sorteada'!E12 -> Rio Brilhante | F12: ='Amostra Sorteada'!F12 -> Centro-Oeste | G12: ='Amostra Sorteada'!L12 -> https://riobrilhante.ms.gov.br/ | H12: ='Amostra Sorteada'!I12 -> Sim | I12: ='Amostra Sorteada'!J12 -> Sim | J12: ='Amostra Sorteada'!K12 -> Apto | K12: ='Amostra Sorteada'!M12 -> 0 | L12: =_xlfn.XLOOKUP($A12,'Tabela 4714 Tratada'!$A:$A,'Tabela 4714 Tratada'!$D:$D,"Não encontrado") -> 37601 | M12: =_xlfn.XLOOKUP($A12,'Tabela 4714 Tratada'!$A:$A,'Tabela 4714 Tratada'!$E:$E,"Não encontrado") -> 3983.562 | N12: =_xlfn.XLOOKUP($A12,'Tabela 4714 Tratada'!$A:$A,'Tabela 4714 Tratada'!$C:$C,"Não encontrado") -> 9.44 | O12: ='Amostra Sorteada'!G12 -> 0.015918488
A13: ='Amostra Sorteada'!C13 -> 5214838 | B13: ='Amostra Sorteada'!A13 -> 52 | C13: ='Amostra Sorteada'!B13 -> Goiás | D13: ='Amostra Sorteada'!D13 -> 14838 | E13: ='Amostra Sorteada'!E13 -> Nova Crixás | F13: ='Amostra Sorteada'!F13 -> Centro-Oeste | G13: ='Amostra Sorteada'!L13 -> https://novacrixas.go.gov.br/ | H13: ='Amostra Sorteada'!I13 -> Sim | I13: ='Amostra Sorteada'!J13 -> Sim | J13: ='Amostra Sorteada'!K13 -> Apto | K13: ='Amostra Sorteada'!M13 -> 0 | L13: =_xlfn.XLOOKUP($A13,'Tabela 4714 Tratada'!$A:$A,'Tabela 4714 Tratada'!$D:$D,"Não encontrado") -> 12815 | M13: =_xlfn.XLOOKUP($A13,'Tabela 4714 Tratada'!$A:$A,'Tabela 4714 Tratada'!$E:$E,"Não encontrado") -> 7308.681 | N13: =_xlfn.XLOOKUP($A13,'Tabela 4714 Tratada'!$A:$A,'Tabela 4714 Tratada'!$C:$C,"Não encontrado") -> 1.75 | O13: ='Amostra Sorteada'!G13 -> 0.016464116
... A389: ='Amostra Sorteada'!C389 -> 4300570 | B389: ='Amostra Sorteada'!A389 -> 43 | C389: ='Amostra Sorteada'!B389 -> Rio Grande do Sul | D389: ='Amostra Sorteada'!D389 -> 00570 | E389: ='Amostra Sorteada'!E389 -> Alto Feliz | F389: ='Amostra Sorteada'!F389 -> Sul | G389: ='Amostra Sorteada'!L389 -> https://www.altofeliz.rs.gov.br/web/ | H389: ='Amostra Sorteada'!I389 -> Sim | I389: ='Amostra Sorteada'!J389 -> Sim | J389: ='Amostra Sorteada'!K389 -> Apto | K389: ='Amostra Sorteada'!M389 -> 0 | L389: =_xlfn.XLOOKUP($A389,'Tabela 4714 Tratada'!$A:$A,'Tabela 4714 Tratada'!$D:$D,"Não encontrado") -> 3072 | M389: =_xlfn.XLOOKUP($A389,'Tabela 4714 Tratada'!$A:$A,'Tabela 4714 Tratada'!$E:$E,"Não encontrado") -> 78.175 | N389: =_xlfn.XLOOKUP($A389,'Tabela 4714 Tratada'!$A:$A,'Tabela 4714 Tratada'!$C:$C,"Não encontrado") -> 39.3 | O389: ='Amostra Sorteada'!G389 -> 0.06913189

Sheet Tabela Dinâmica Base Amostral
A1: status_validacao_url | B1: Apto
A3: regiao | B3: Contagem de URL | D3: Amostra Calculada
A4: Centro-Oeste | B4: 31 | D4: 31
A5: Nordeste | B5: 116 | D5: 116
A6: Norte | B6: 30 | D6: 30
A7: Sudeste | B7: 108 | D7: 108
A8: Sul | B8: 77 | D8: 77
A9: Total Geral | B9: 362 | D9: 362

Sheet Base Amostral Consolidada
A1: codigo_municipio_completo | B1: codigo_uf | C1: nome_uf | D1: codigo_municipio | E1: nome_municipio | F1: regiao | G1: url | H1: site_encontrado | I1: url_confiavel | J1: status_validacao_url | K1: observacao | L1: populacao_residente_2022 | M1: area_territorial_km2 | N1: densidade_demografica_hab_km2 | O1: chave_aleatoria
A2: 5107909 | B2: 51 | C2: Mato Grosso | D2: 07909 | E2: Sinop | F2: Centro-Oeste | G2: https://www.sinop.mt.gov.br/ | H2: Sim | I2: Sim | J2: Apto | K2: 0 | L2: 196312 | M2: 3990.87 | N2: 49.19 | O2: 0.0025088861
A3: 5108402 | B3: 51 | C3: Mato Grosso | D3: 08402 | E3: Várzea Grande | F3: Centro-Oeste | G3: https://www.varzeagrande.mt.gov.br/ | H3: Sim | I3: Sim | J3: Apto | K3: 0 | L3: 300078 | M3: 724.279 | N3: 414.31 | O3: 0.0042295342
A4: 5206602 | B4: 52 | C4: Goiás | D4: 06602 | E4: Cumari | F4: Centro-Oeste | G4: https://cumari.go.gov.br/ | H4: Sim | I4: Sim | J4: Apto | K4: 0 | L4: 2927 | M4: 568.365 | N4: 5.15 | O4: 0.005838812
A5: 5220454 | B5: 52 | C5: Goiás | D5: 20454 | E5: Senador Canedo | F5: Centro-Oeste | G5: https://senadorcanedo.go.gov.br/ | H5: Sim | I5: Sim | J5: Apto | K5: 0 | L5: 155635 | M5: 247.005 | N5: 630.09 | O5: 0.0062921544
A6: 5207253 | B6: 52 | C6: Goiás | D6: 07253 | E6: Doverlândia | F6: Centro-Oeste | G6: https://doverlandia.go.gov.br/ | H6: Sim | I6: Sim | J6: Apto | K6: 0 | L6: 6956 | M6: 3227.558 | N6: 2.16 | O6: 0.0064175894
A7: 5103437 | B7: 51 | C7: Mato Grosso | D7: 03437 | E7: Curvelândia | F7: Centro-Oeste | G7: https://www.curvelandia.mt.gov.br/ | H7: Sim | I7: Sim | J7: Apto | K7: 0 | L7: 4903 | M7: 357.128 | N7: 13.73 | O7: 0.0065792411
A8: 5204656 | B8: 52 | C8: Goiás | D8: 04656 | E8: Campinaçu | F8: Centro-Oeste | G8: https://www.campinacu.go.gov.br/ | H8: Sim | I8: Sim | J8: Apto | K8: 0 | L8: 3708 | M8: 1978.386 | N8: 1.87 | O8: 0.008315084
A9: 5213905 | B9: 52 | C9: Goiás | D9: 13905 | E9: Mossâmedes | F9: Centro-Oeste | G9: http://mossamedes.go.gov.br/ | H9: Sim | I9: Sim | J9: Apto | K9: 0 | L9: 4654 | M9: 684.882 | N9: 6.8 | O9: 0.010133321
A10: 5002704 | B10: 50 | C10: Mato Grosso do Sul | D10: 02704 | E10: Campo Grande | F10: Centro-Oeste | G10: https://www.campogrande.ms.gov.br/ | H10: Sim | I10: Sim | J10: Apto | K10: 0 | L10: 898100 | M10: 8082.978 | N10: 111.11 | O10: 0.011278
A11: 5210802 | B11: 52 | C11: Goiás | D11: 10802 | E11: Itajá | F11: Centro-Oeste | G11: https://itaja.go.gov.br/ | H11: Sim | I11: Sim | J11: Apto | K11: 0 | L11: 4380 | M11: 2082.736 | N11: 2.1 | O11: 0.012106377
A12: 5007208 | B12: 50 | C12: Mato Grosso do Sul | D12: 07208 | E12: Rio Brilhante | F12: Centro-Oeste | G12: https://riobrilhante.ms.gov.br/ | H12: Sim | I12: Sim | J12: Apto | K12: 0 | L12: 37601 | M12: 3983.562 | N12: 9.44 | O12: 0.015918488
A13: 5214838 | B13: 52 | C13: Goiás | D13: 14838 | E13: Nova Crixás | F13: Centro-Oeste | G13: https://novacrixas.go.gov.br/ | H13: Sim | I13: Sim | J13: Apto | K13: 0 | L13: 12815 | M13: 7308.681 | N13: 1.75 | O13: 0.016464116
... A141: 2304236 | B141: 23 | C141: Ceará | D141: 04236 | E141: Croatá | F141: Nordeste | G141: https://croata.ce.gov.br/ | H141: Sim | I141: Sim | J141: Apto | K141: 0 | L141: 17481 | M141: 696.348 | N141: 25.1 | O141: 0.071170911
A142: 2206407 | B142: 22 | C142: Piauí | D142: 06407 | E142: Monsenhor Gil | F142: Nordeste | G142: https://monsenhorgil.pi.gov.br/ | H142: Sim | I142: Sim | J142: Apto | K142: 0 | L142: Não encontrado | M142: Não encontrado | N142: Não encontrado | O142: 0.071459944
A143: 2105203 | B143: 21 | C143: Maranhão | D143: 05203 | E143: Igarapé Grande | F143: Nordeste | G143: https://www.igarapegrande.ma.gov.br/ | H143: Sim | I143: Sim | J143: Apto | K143: 0 | L143: Não encontrado | M143: Não encontrado | N143: Não encontrado | O143: 0.071777594
A144: 2105104 | B144: 21 | C144: Maranhão | D144: 05104 | E144: Icatu | F144: Nordeste | G144: https://www.icatu.ma.gov.br/ | H144: Sim | I144: Sim | J144: Apto | K144: 0 | L144: Não encontrado | M144: Não encontrado | N144: Não encontrado | O144: 0.072415158
A145: 2504074 | B145: 25 | C145: Paraíba | D145: 04074 | E145: Caraúbas | F145: Nordeste | G145: https://caraubas.rn.gov.br/ | H145: Sim | I145: Sim | J145: Apto | K145: 0 | L145: Não encontrado | M145: Não encontrado | N145: Não encontrado | O145: 0.072676517
A146: 2109809 | B146: 21 | C146: Maranhão | D146: 09809 | E146: Santa Helena | F146: Nordeste | G146: https://santahelena.ma.gov.br/ | H146: Sim | I146: Sim | J146: Apto | K146: 0 | L146: Não encontrado | M146: Não encontrado | N146: Não encontrado | O146: 0.073116644
A147: 2614501 | B147: 26 | C147: Pernambuco | D147: 14501 | E147: Surubim | F147: Nordeste | G147: https://surubim.pe.gov.br/ | H147: Sim | I147: Sim | J147: Apto | K147: 0 | L147: 64120 | M147: 252.896 | N147: 253.54 | O147: 0.073506142
A148: 2927002 | B148: 29 | C148: Bahia | D148: 27002 | E148: Rio Real | F148: Nordeste | G148: https://rioreal.ba.gov.br/ | H148: Sim | I148: Sim | J148: Apto | K148: 0 | L148: 35362 | M148: 739.775 | N148: 47.8 | O148: 0.074273743
A149: 1502707 | B149: 15 | C149: Pará | D149: 02707 | E149: Conceição do Araguaia | F149: Norte | G149: https://www.conceicaodoaraguaia.pa.gov.br/ | H149: Sim | I149: Sim | J149: Apto | K149: 0 | L149: 44617 | M149: 5829.482 | N149: 7.65 | O149: 0.0020901788
A150: 1303403 | B150: 13 | C150: Amazonas | D150: 03403 | E150: Parintins | F150: Norte | G150: https://www.parintins.am.gov.br/ | H150: Sim | I150: Sim | J150: Apto | K150: 0 | L150: 96372 | M150: 5956.047 | N150: 16.18 | O150: 0.003152961
A151: 1101807 | B151: 11 | C151: Rondônia | D151: 01807 | E151: Vale do Paraíso | F151: Norte | G151: https://www.valedoparaiso.ro.gov.br/ | H151: Sim | I151: Sim | J151: Apto | K151: 0 | L151: 6479 | M151: 965.676 | N151: 6.71 | O151: 0.0038624026
A152: 1600550 | B152: 16 | C152: Amapá | D152: 00550 | E152: Pracuúba | F152: Norte | G152: https://www.pracuuba.ap.gov.br/ | H152: Sim | I152: Sim | J152: Apto | K152: 0 | L152: 3803 | M152: 4948.508 | N152: 0.77 | O152: 0.005229401
A153: 1718808 | B153: 17 | C153: Tocantins | D153: 18808 | E153: Sampaio | F153: Norte | G153: https://www.sampaio.to.gov.br/ | H153: Sim | I153: Sim | J153: Apto | K153: 0 | L153: 4215 | M153: 222.435 | N153: 18.95 | O153: 0.014196673
A154: 1702208 | B154: 17 | C154: Tocantins | D154: 02208 | E154: Araguatins | F154: Norte | G154: https://www.araguatins.to.gov.br/ | H154: Sim | I154: Sim | J154: Apto | K154: 0 | L154: 31918 | M154: 2633.278 | N154: 12.12 | O154: 0.014233899
A155: 1600709 | B155: 16 | C155: Amapá | D155: 00709 | E155: Tartarugalzinho | F155: Norte | G155: https://www.tartarugalzinho.ap.gov.br/ | H155: Sim | I155: Sim | J155: Apto | K155: 0 | L155: 12945 | M155: 6684.705 | N155: 1.94 | O155: 0.014378356
