Workbook

Sheet Base_Amostral
A1: codigo_municipio_completo | B1: codigo_uf | C1: nome_uf | D1: codigo_municipio | E1: nome_municipio | F1: regiao | G1: url | H1: site_encontrado | I1: url_confiavel | J1: status_validacao_url | K1: populacao_residente_2022 | L1: area_territorial_km2 | M1: densidade_demografica_hab_km2 | N1: chave_aleatoria | O1: observacao
A2: 5107909 | B2: 51 | C2: Mato Grosso | D2: 7909 | E2: Sinop | F2: Centro-Oeste | G2: https://www.sinop.mt.gov.br/ | H2: Sim | I2: Sim | J2: Apto | K2: 196312 | L2: 3990,87 | M2: 49,19 | N2: 0.002508886 | O2: 0
A3: 5108402 | B3: 51 | C3: Mato Grosso | D3: 8402 | E3: Várzea Grande | F3: Centro-Oeste | G3: https://www.varzeagrande.mt.gov.br/ | H3: Sim | I3: Sim | J3: Apto | K3: 300078 | L3: 724,279 | M3: 414,31 | N3: 0.004229534 | O3: 0
A4: 5206602 | B4: 52 | C4: Goiás | D4: 6602 | E4: Cumari | F4: Centro-Oeste | G4: https://cumari.go.gov.br/ | H4: Sim | I4: Sim | J4: Apto | K4: 2927 | L4: 568,365 | M4: 5,15 | N4: 0.005838812 | O4: 0
A5: 5220454 | B5: 52 | C5: Goiás | D5: 20454 | E5: Senador Canedo | F5: Centro-Oeste | G5: https://senadorcanedo.go.gov.br/ | H5: Sim | I5: Sim | J5: Apto | K5: 155635 | L5: 247,005 | M5: 630,09 | N5: 0.006292154 | O5: 0
A6: 5207253 | B6: 52 | C6: Goiás | D6: 7253 | E6: Doverlândia | F6: Centro-Oeste | G6: https://doverlandia.go.gov.br/ | H6: Sim | I6: Sim | J6: Apto | K6: 6956 | L6: 3227,558 | M6: 2,16 | N6: 0.006417589 | O6: 0
A7: 5103437 | B7: 51 | C7: Mato Grosso | D7: 3437 | E7: Curvelândia | F7: Centro-Oeste | G7: https://www.curvelandia.mt.gov.br/ | H7: Sim | I7: Sim | J7: Apto | K7: 4903 | L7: 357,128 | M7: 13,73 | N7: 0.006579241 | O7: 0
A8: 5204656 | B8: 52 | C8: Goiás | D8: 4656 | E8: Campinaçu | F8: Centro-Oeste | G8: https://www.campinacu.go.gov.br/ | H8: Sim | I8: Sim | J8: Apto | K8: 3708 | L8: 1978,386 | M8: 1,87 | N8: 0.008315084 | O8: 0
A9: 5213905 | B9: 52 | C9: Goiás | D9: 13905 | E9: Mossâmedes | F9: Centro-Oeste | G9: http://mossamedes.go.gov.br/ | H9: Sim | I9: Sim | J9: Apto | K9: 4654 | L9: 684,882 | M9: 6,8 | N9: 0.010133321 | O9: 0
A10: 5002704 | B10: 50 | C10: Mato Grosso do Sul | D10: 2704 | E10: Campo Grande | F10: Centro-Oeste | G10: https://www.campogrande.ms.gov.br/ | H10: Sim | I10: Sim | J10: Apto | K10: 898100 | L10: 8082,978 | M10: 111,11 | N10: 0.011278 | O10: 0
A11: 5210802 | B11: 52 | C11: Goiás | D11: 10802 | E11: Itajá | F11: Centro-Oeste | G11: https://itaja.go.gov.br/ | H11: Sim | I11: Sim | J11: Apto | K11: 4380 | L11: 2082,736 | M11: 2,1 | N11: 0.012106377 | O11: 0
A12: 5007208 | B12: 50 | C12: Mato Grosso do Sul | D12: 7208 | E12: Rio Brilhante | F12: Centro-Oeste | G12: https://riobrilhante.ms.gov.br/ | H12: Sim | I12: Sim | J12: Apto | K12: 37601 | L12: 3983,562 | M12: 9,44 | N12: 0.015918488 | O12: 0
A13: 5214838 | B13: 52 | C13: Goiás | D13: 14838 | E13: Nova Crixás | F13: Centro-Oeste | G13: https://novacrixas.go.gov.br/ | H13: Sim | I13: Sim | J13: Apto | K13: 12815 | L13: 7308,681 | M13: 1,75 | N13: 0.016464116 | O13: 0
... A141: 2304236 | B141: 23 | C141: Ceará | D141: 4236 | E141: Croatá | F141: Nordeste | G141: https://croata.ce.gov.br/ | H141: Sim | I141: Sim | J141: Apto | K141: 17481 | L141: 696,348 | M141: 25,1 | N141: 0.071170911 | O141: 0
A142: 2206407 | B142: 22 | C142: Piauí | D142: 6407 | E142: Monsenhor Gil | F142: Nordeste | G142: https://monsenhorgil.pi.gov.br/ | H142: Sim | I142: Sim | J142: Apto | K142: 10255 | L142: 567.86 | M142: 18.06 | N142: 0.071459944 | O142: 0
A143: 2105203 | B143: 21 | C143: Maranhão | D143: 5203 | E143: Igarapé Grande | F143: Nordeste | G143: https://www.igarapegrande.ma.gov.br/ | H143: Sim | I143: Sim | J143: Apto | K143: 10231 | L143: 346.218 | M143: 29.55 | N143: 0.071777594 | O143: 0
A144: 2105104 | B144: 21 | C144: Maranhão | D144: 5104 | E144: Icatu | F144: Nordeste | G144: https://www.icatu.ma.gov.br/ | H144: Sim | I144: Sim | J144: Apto | K144: 24794 | L144: 1124.445 | M144: 22.05 | N144: 0.072415158 | O144: 0
A145: 2504074 | B145: 25 | C145: Paraíba | D145: 4074 | E145: Caraúbas | F145: Nordeste | G145: https://caraubas.rn.gov.br/ | H145: Sim | I145: Sim | J145: Apto | K145: 19727 | L145: 1095.803 | M145: 18 | N145: 0.072676517 | O145: 0
A146: 2109809 | B146: 21 | C146: Maranhão | D146: 9809 | E146: Santa Helena | F146: Nordeste | G146: https://santahelena.ma.gov.br/ | H146: Sim | I146: Sim | J146: Apto | K146: 41561 | L146: 2191.168 | M146: 18.97 | N146: 0.073116644 | O146: 0
A147: 2614501 | B147: 26 | C147: Pernambuco | D147: 14501 | E147: Surubim | F147: Nordeste | G147: https://surubim.pe.gov.br/ | H147: Sim | I147: Sim | J147: Apto | K147: 64120 | L147: 252,896 | M147: 253,54 | N147: 0.073506142 | O147: 0
A148: 2927002 | B148: 29 | C148: Bahia | D148: 27002 | E148: Rio Real | F148: Nordeste | G148: https://rioreal.ba.gov.br/ | H148: Sim | I148: Sim | J148: Apto | K148: 35362 | L148: 739,775 | M148: 47,8 | N148: 0.074273743 | O148: 0
A149: 1502707 | B149: 15 | C149: Pará | D149: 2707 | E149: Conceição do Araguaia | F149: Norte | G149: https://www.conceicaodoaraguaia.pa.gov.br/ | H149: Sim | I149: Sim | J149: Apto | K149: 44617 | L149: 5829,482 | M149: 7,65 | N149: 0.002090179 | O149: 0
A150: 1303403 | B150: 13 | C150: Amazonas | D150: 3403 | E150: Parintins | F150: Norte | G150: https://www.parintins.am.gov.br/ | H150: Sim | I150: Sim | J150: Apto | K150: 96372 | L150: 5956,047 | M150: 16,18 | N150: 0.003152961 | O150: 0
A151: 1101807 | B151: 11 | C151: Rondônia | D151: 1807 | E151: Vale do Paraíso | F151: Norte | G151: https://www.valedoparaiso.ro.gov.br/ | H151: Sim | I151: Sim | J151: Apto | K151: 6479 | L151: 965,676 | M151: 6,71 | N151: 0.003862403 | O151: 0
A152: 1600550 | B152: 16 | C152: Amapá | D152: 550 | E152: Pracuúba | F152: Norte | G152: https://www.pracuuba.ap.gov.br/ | H152: Sim | I152: Sim | J152: Apto | K152: 3803 | L152: 4948,508 | M152: 0,77 | N152: 0.005229401 | O152: 0
A153: 1718808 | B153: 17 | C153: Tocantins | D153: 18808 | E153: Sampaio | F153: Norte | G153: https://www.sampaio.to.gov.br/ | H153: Sim | I153: Sim | J153: Apto | K153: 4215 | L153: 222,435 | M153: 18,95 | N153: 0.014196673 | O153: 0
A154: 1702208 | B154: 17 | C154: Tocantins | D154: 2208 | E154: Araguatins | F154: Norte | G154: https://www.araguatins.to.gov.br/ | H154: Sim | I154: Sim | J154: Apto | K154: 31918 | L154: 2633,278 | M154: 12,12 | N154: 0.014233899 | O154: 0
A155: 1600709 | B155: 16 | C155: Amapá | D155: 709 | E155: Tartarugalzinho | F155: Norte | G155: https://www.tartarugalzinho.ap.gov.br/ | H155: Sim | I155: Sim | J155: Apto | K155: 12945 | L155: 6684,705 | M155: 1,94 | N155: 0.014378356 | O155: 0
A156: 1200393 | B156: 12 | C156: Acre | D156: 393 | E156: Porto Walter | F156: Norte | G156: https://www.portowalter.ac.gov.br/ | H156: Sim | I156: Sim | J156: Apto | K156: 10735 | L156: 6446,385 | M156: 1,67 | N156: 0.015577227 | O156: 0
A157: 1300839 | B157: 13 | C157: Amazonas | D157: 839 | E157: Caapiranga | F157: Norte | G157: https://www.caapiranga.am.gov.br/ | H157: Sim | I157: Sim | J157: Apto | K157: 13469 | L157: 9455,539 | M157: 1,42 | N157: 0.016174427 | O157: 0
A158: 1100015 | B158: 11 | C158: Rondônia | D158: 15 | E158: Alta Floresta D'Oeste | F158: Norte | G158: https://www.altaflorestadoeste.ro.gov.br/ | H158: Sim | I158: Sim | J158: Apto | K158: 21494 | L158: 7067,127 | M158: 3,04 | N158: 0.016815501 | O158: 0
... A363: 4300570 | B363: 43 | C363: Rio Grande do Sul | D363: 570 | E363: Alto Feliz | F363: Sul | G363: https://www.altofeliz.rs.gov.br/web/ | H363: Sim | I363: Sim | J363: Apto | K363: 3072 | L363: 78,175 | M363: 39,3 | N363: 0.06913189 | O363: 0

Sheet Execucoes
A1: id_execucao | B1: rodada | C1: sessao | D1: codigo_municipio_completo | E1: nota_amaweb | F1: status_amaweb | G1: avaliado_amaweb_em | H1: nota_accessmonitor | I1: status_accessmonitor | J1: avaliado_accessmonitor_em | K1: tem_resultado_amaweb | L1: tem_resultado_accessmonitor | M1: status_geral | N1: observacao_analise | O1: criado_em | P1: atualizado_em | Q1: chave_municipio_rodada
A2: 1 | B2: r00 | C2: 2026-06-20_00-25-00__validacao_tcc_unifal_r00 | D2: 1200179 | E2: 61 | F2: sucesso | G2: 46193.018 | H2: 61 | I2: sucesso | J2: 46193.019 | K2: 1 | L2: 1 | M2: completo | O2: 46193.018 | P2: 46193.019 | Q2: =D2&"|"&B2 -> 1200179|r00
A3: 2 | B3: r00 | C3: 2026-06-20_00-25-00__validacao_tcc_unifal_r00 | D3: 2700102 | E3: 57 | F3: sucesso | G3: 46193.02 | I3: sucesso_sem_nota | J3: 46193.021 | K3: 1 | L3: 0 | M3: parcial | O3: 46193.018 | P3: 46193.021 | Q3: =D3&"|"&B3 -> 2700102|r00
A4: 3 | B4: r00 | C4: 2026-06-20_00-25-00__validacao_tcc_unifal_r00 | D4: 5203939 | E4: 75 | F4: sucesso | G4: 46193.018 | H4: 72 | I4: sucesso | J4: 46193.018 | K4: 1 | L4: 1 | M4: completo | O4: 46193.018 | P4: 46193.018 | Q4: =D4&"|"&B4 -> 5203939|r00
A5: 4 | B5: r00 | C5: 2026-06-20_00-25-00__validacao_tcc_unifal_r00 | D5: 5204656 | E5: 69 | F5: sucesso | G5: 46193.019 | H5: 69 | I5: sucesso | J5: 46193.019 | K5: 1 | L5: 1 | M5: completo | O5: 46193.018 | P5: 46193.019 | Q5: =D5&"|"&B5 -> 5204656|r00
A6: 5 | B6: r00 | C6: 2026-06-20_00-25-00__validacao_tcc_unifal_r00 | D6: 1200393 | E6: 61 | F6: sucesso | G6: 46193.021 | H6: 61 | I6: sucesso | J6: 46193.022 | K6: 1 | L6: 1 | M6: completo | O6: 46193.019 | P6: 46193.022 | Q6: =D6&"|"&B6 -> 1200393|r00
A7: 6 | B7: r00 | C7: 2026-06-20_00-25-00__validacao_tcc_unifal_r00 | D7: 5205802 | E7: 74 | F7: sucesso | G7: 46193.019 | H7: 74 | I7: sucesso | J7: 46193.02 | K7: 1 | L7: 1 | M7: completo | O7: 46193.019 | P7: 46193.02 | Q7: =D7&"|"&B7 -> 5205802|r00
A8: 7 | B8: r00 | C8: 2026-06-20_00-25-00__validacao_tcc_unifal_r00 | D8: 5206602 | E8: 70 | F8: sucesso | G8: 46193.02 | H8: 69 | I8: sucesso | J8: 46193.02 | K8: 1 | L8: 1 | M8: completo | O8: 46193.02 | P8: 46193.02 | Q8: =D8&"|"&B8 -> 5206602|r00
A9: 8 | B9: r00 | C9: 2026-06-20_00-25-00__validacao_tcc_unifal_r00 | D9: 5207253 | E9: 76 | F9: sucesso | G9: 46193.021 | H9: 78 | I9: sucesso | J9: 46193.021 | K9: 1 | L9: 1 | M9: completo | O9: 46193.02 | P9: 46193.021 | Q9: =D9&"|"&B9 -> 5207253|r00
A10: 9 | B10: r00 | C10: 2026-06-20_00-25-00__validacao_tcc_unifal_r00 | D10: 2702207 | E10: 54 | F10: sucesso | G10: 46193.021 | H10: 58 | I10: sucesso | J10: 46193.021 | K10: 1 | L10: 1 | M10: completo | O10: 46193.021 | P10: 46193.021 | Q10: =D10&"|"&B10 -> 2702207|r00
A11: 10 | B11: r00 | C11: 2026-06-20_00-25-00__validacao_tcc_unifal_r00 | D11: 5208806 | E11: 70 | F11: sucesso | G11: 46193.021 | H11: 72 | I11: sucesso | J11: 46193.022 | K11: 1 | L11: 1 | M11: completo | O11: 46193.021 | P11: 46193.022 | Q11: =D11&"|"&B11 -> 5208806|r00
A12: 11 | B12: r00 | C12: 2026-06-20_00-25-00__validacao_tcc_unifal_r00 | D12: 2702900 | E12: 64 | F12: sucesso | G12: 46193.022 | H12: 68 | I12: sucesso | J12: 46193.022 | K12: 1 | L12: 1 | M12: completo | O12: 46193.021 | P12: 46193.022 | Q12: =D12&"|"&B12 -> 2702900|r00
A13: 12 | B13: r00 | C13: 2026-06-20_00-25-00__validacao_tcc_unifal_r00 | D13: 5209457 | E13: 73 | F13: sucesso | G13: 46193.022 | H13: 72 | I13: sucesso | J13: 46193.022 | K13: 1 | L13: 1 | M13: completo | O13: 46193.022 | P13: 46193.022 | Q13: =D13&"|"&B13 -> 5209457|r00
A14: 13 | B14: r00 | C14: 2026-06-20_00-25-00__validacao_tcc_unifal_r00 | D14: 1600303 | E14: 92 | F14: sucesso | G14: 46193.022 | I14: sucesso_sem_nota | J14: 46193.023 | K14: 1 | L14: 0 | M14: parcial | O14: 46193.022 | P14: 46193.023 | Q14: =D14&"|"&B14 -> 1600303|r00
A15: 14 | B15: r00 | C15: 2026-06-20_00-25-00__validacao_tcc_unifal_r00 | D15: 2703304 | E15: 64 | F15: sucesso | G15: 46193.023 | H15: 60 | I15: sucesso | J15: 46193.023 | K15: 1 | L15: 1 | M15: completo | O15: 46193.022 | P15: 46193.023 | Q15: =D15&"|"&B15 -> 2703304|r00
A16: 15 | B16: r00 | C16: 2026-06-20_00-25-00__validacao_tcc_unifal_r00 | D16: 5210802 | E16: 63 | F16: sucesso | G16: 46193.023 | H16: 62 | I16: sucesso | J16: 46193.023 | K16: 1 | L16: 1 | M16: completo | O16: 46193.022 | P16: 46193.023 | Q16: =D16&"|"&B16 -> 5210802|r00
A17: 16 | B17: r00 | C17: 2026-06-20_00-25-00__validacao_tcc_unifal_r00 | D17: 2706422 | E17: 58 | F17: sucesso | G17: 46193.023 | H17: 57 | I17: sucesso | J17: 46193.023 | K17: 1 | L17: 1 | M17: completo | O17: 46193.023 | P17: 46193.023 | Q17: =D17&"|"&B17 -> 2706422|r00
A18: 17 | B18: r00 | C18: 2026-06-20_00-25-00__validacao_tcc_unifal_r00 | D18: 5211800 | E18: 70 | F18: sucesso | G18: 46193.023 | H18: 71 | I18: sucesso | J18: 46193.024 | K18: 1 | L18: 1 | M18: completo | O18: 46193.023 | P18: 46193.024 | Q18: =D18&"|"&B18 -> 5211800|r00
A19: 18 | B19: r00 | C19: 2026-06-20_00-25-00__validacao_tcc_unifal_r00 | D19: 1600550 | E19: 65 | F19: sucesso | G19: 46193.024 | H19: 68 | I19: sucesso | J19: 46193.024 | K19: 1 | L19: 1 | M19: completo | O19: 46193.023 | P19: 46193.024 | Q19: =D19&"|"&B19 -> 1600550|r00
A20: 19 | B20: r00 | C20: 2026-06-20_00-25-00__validacao_tcc_unifal_r00 | D20: 2708808 | E20: 52 | F20: sucesso | G20: 46193.024 | H20: 52 | I20: sucesso | J20: 46193.024 | K20: 1 | L20: 1 | M20: completo | O20: 46193.023 | P20: 46193.024 | Q20: =D20&"|"&B20 -> 2708808|r00
A21: 20 | B21: r00 | C21: 2026-06-20_00-25-00__validacao_tcc_unifal_r00 | D21: 5213806 | E21: 76 | F21: sucesso | G21: 46193.024 | H21: 73 | I21: sucesso | J21: 46193.024 | K21: 1 | L21: 1 | M21: completo | O21: 46193.024 | P21: 46193.024 | Q21: =D21&"|"&B21 -> 5213806|r00
A22: 21 | B22: r00 | C22: 2026-06-20_00-25-00__validacao_tcc_unifal_r00 | D22: 1600709 | E22: 59 | F22: sucesso | G22: 46193.024 | H22: 66 | I22: sucesso | J22: 46193.025 | K22: 1 | L22: 1 | M22: completo | O22: 46193.024 | P22: 46193.025 | Q22: =D22&"|"&B22 -> 1600709|r00
A23: 22 | B23: r00 | C23: 2026-06-20_00-25-00__validacao_tcc_unifal_r00 | D23: 2900603 | E23: 60 | F23: sucesso | G23: 46193.025 | H23: 61 | I23: sucesso | J23: 46193.025 | K23: 1 | L23: 1 | M23: completo | O23: 46193.024 | P23: 46193.025 | Q23: =D23&"|"&B23 -> 2900603|r00
A24: 23 | B24: r00 | C24: 2026-06-20_00-25-00__validacao_tcc_unifal_r00 | D24: 5213905 | E24: 76 | F24: sucesso | G24: 46193.025 | H24: 75 | I24: sucesso | J24: 46193.025 | K24: 1 | L24: 1 | M24: completo | O24: 46193.024 | P24: 46193.025 | Q24: =D24&"|"&B24 -> 5213905|r00
A25: 24 | B25: r00 | C25: 2026-06-20_00-25-00__validacao_tcc_unifal_r00 | D25: 1300508 | E25: 92 | F25: sucesso | G25: 46193.025 | H25: 71 | I25: sucesso | J25: 46193.025 | K25: 1 | L25: 1 | M25: completo | O25: 46193.025 | P25: 46193.025 | Q25: =D25&"|"&B25 -> 1300508|r00
A26: 25 | B26: r00 | C26: 2026-06-20_00-25-00__validacao_tcc_unifal_r00 | D26: 2901106 | E26: 79 | F26: sucesso | G26: 46193.025 | H26: 82 | I26: sucesso | J26: 46193.025 | K26: 1 | L26: 1 | M26: completo | O26: 46193.025 | P26: 46193.025 | Q26: =D26&"|"&B26 -> 2901106|r00
... A35: 34 | B35: r00 | C35: 2026-06-20_00-25-00__validacao_tcc_unifal_r00 | D35: 5216908 | E35: 74 | F35: sucesso | G35: 46193.027 | H35: 72 | I35: sucesso | J35: 46193.027 | K35: 1 | L35: 1 | M35: completo | O35: 46193.026 | P35: 46193.027 | Q35: =D35&"|"&B35 -> 5216908|r00
A36: 35 | B36: r00 | C36: 2026-06-20_00-25-00__validacao_tcc_unifal_r00 | D36: 1303403 | E36: 92 | F36: sucesso | G36: 46193.027 | I36: sucesso_sem_nota | J36: 46193.028 | K36: 1 | L36: 0 | M36: parcial | O36: 46193.027 | P36: 46193.028 | Q36: =D36&"|"&B36 -> 1303403|r00
A37: 36 | B37: r00 | C37: 2026-06-20_00-25-00__validacao_tcc_unifal_r00 | D37: 5220454 | E37: 67 | F37: sucesso | G37: 46193.027 | H37: 69 | I37: sucesso | J37: 46193.028 | K37: 1 | L37: 1 | M37: completo | O37: 46193.027 | P37: 46193.028 | Q37: =D37&"|"&B37 -> 5220454|r00
A38: 37 | B38: r00 | C38: 2026-06-20_00-25-00__validacao_tcc_unifal_r00 | D38: 2911402 | E38: 80 | F38: sucesso | G38: 46193.027 | H38: 83 | I38: sucesso | J38: 46193.028 | K38: 1 | L38: 1 | M38: completo | O38: 46193.027 | P38: 46193.028 | Q38: =D38&"|"&B38 -> 2911402|r00
A39: 38 | B39: r00 | C39: 2026-06-20_00-25-00__validacao_tcc_unifal_r00 | D39: 2912103 | E39: 53 | F39: sucesso | G39: 46193.028 | H39: 54 | I39: sucesso | J39: 46193.028 | K39: 1 | L39: 1 | M39: completo | O39: 46193.028 | P39: 46193.028 | Q39: =D39&"|"&B39 -> 2912103|r00
A40: 39 | B40: r00 | C40: 2026-06-20_00-25-00__validacao_tcc_unifal_r00 | D40: 5100102 | F40: falha_de_carregamento | G40: 46193.035 | H40: 63 | I40: sucesso | J40: 46193.035 | K40: 0 | L40: 1 | M40: parcial | O40: 46193.028 | P40: 46193.035 | Q40: =D40&"|"&B40 -> 5100102|r00
A41: 40 | B41: r00 | C41: 2026-06-20_00-25-00__validacao_tcc_unifal_r00 | D41: 1500107 | F41: falha_de_carregamento | G41: 46193.035 | H41: 60 | I41: sucesso | J41: 46193.036 | K41: 0 | L41: 1 | M41: parcial | O41: 46193.028 | P41: 46193.036 | Q41: =D41&"|"&B41 -> 1500107|r00
A42: 41 | B42: r00 | C42: 2026-06-20_00-25-00__validacao_tcc_unifal_r00 | D42: 2913705 | E42: 50 | F42: sucesso | G42: 46193.029 | H42: 57 | I42: sucesso | J42: 46193.029 | K42: 1 | L42: 1 | M42: completo | O42: 46193.028 | P42: 46193.029 | Q42: =D42&"|"&B42 -> 2913705|r00
A43: 42 | B43: r00 | C43: 2026-06-20_00-25-00__validacao_tcc_unifal_r00 | D43: 2915007 | F43: falha_de_carregamento | G43: 46193.036 | I43: sucesso_sem_nota | J43: 46193.037 | K43: 0 | L43: 0 | M43: falha_total | O43: 46193.029 | P43: 46193.037 | Q43: =D43&"|"&B43 -> 2915007|r00
A44: 43 | B44: r00 | C44: 2026-06-20_00-25-00__validacao_tcc_unifal_r00 | D44: 5101902 | E44: 51 | F44: sucesso | G44: 46193.037 | H44: 52 | I44: sucesso | J44: 46193.037 | K44: 1 | L44: 1 | M44: completo | O44: 46193.035 | P44: 46193.037 | Q44: =D44&"|"&B44 -> 5101902|r00
A45: 44 | B45: r00 | C45: 2026-06-20_00-25-00__validacao_tcc_unifal_r00 | D45: 1500958 | E45: 62 | F45: sucesso | G45: 46193.036 | H45: 64 | I45: sucesso | J45: 46193.036 | K45: 1 | L45: 1 | M45: completo | O45: 46193.036 | P45: 46193.036 | Q45: =D45&"|"&B45 -> 1500958|r00
A46: 45 | B46: r00 | C46: 2026-06-20_00-25-00__validacao_tcc_unifal_r00 | D46: 1502707 | E46: 92 | F46: sucesso | G46: 46193.04 | H46: 61 | I46: sucesso | J46: 46193.04 | K46: 1 | L46: 1 | M46: completo | O46: 46193.036 | P46: 46193.04 | Q46: =D46&"|"&B46 -> 1502707|r00
A47: 46 | B47: r00 | C47: 2026-06-20_00-25-00__validacao_tcc_unifal_r00 | D47: 5102504 | E47: 66 | F47: sucesso | G47: 46193.037 | H47: 72 | I47: sucesso | J47: 46193.038 | K47: 1 | L47: 1 | M47: completo | O47: 46193.037 | P47: 46193.038 | Q47: =D47&"|"&B47 -> 5102504|r00
A48: 47 | B48: r00 | C48: 2026-06-20_00-25-00__validacao_tcc_unifal_r00 | D48: 2915106 | E48: 92 | F48: sucesso | G48: 46193.039 | H48: 73 | I48: sucesso | J48: 46193.04 | K48: 1 | L48: 1 | M48: completo | O48: 46193.037 | P48: 46193.04 | Q48: =D48&"|"&B48 -> 2915106|r00
...

Sheet Logs
A1: id_log | B1: rodada | C1: sessao | D1: codigo_municipio_completo | E1: ferramenta | F1: tentativa | G1: url_enviada | H1: url_final | I1: dominio_final | J1: houve_redirecionamento | K1: titulo_pagina | L1: inicio_em | M1: fim_em | N1: duracao_segundos | O1: status_tentativa | P1: nota_extraida | Q1: nota_bruta | R1: caminho_pdf | S1: caminho_csv | T1: caminho_print | U1: caminho_json | V1: mensagem_erro | W1: traceback_resumido | X1: criado_em
A2: 1 | B2: r00 | C2: 2026-06-20_00-25-00__validacao_tcc_unifal_r00 | D2: 5203939 | E2: amaweb | F2: 1 | G2: https://buritidegoias.go.gov.br/ | H2: https://amaweb.unifesp.br/avaliador/results/https%3A%2F%2Fburitidegoias.go.gov.br%2F | I2: amaweb.unifesp.br | J2: 1 | K2: AMAWeb | Avaliador | L2: 46193.018 | M2: 46193.018 | N2: 4507 | O2: sucesso | P2: 75 | Q2: 7.5 | R2: /media/serv-bot/cebece73-ca34-45fa-ba0e-9a1a1807e5c3/TCC_Unifal/Evidencias_TCC_Unifal/relatorios_ferramentas/2026-06-20_00-25-00__validacao_tcc_unifal_r00/amaweb/buriti-de-goias-goias-5203939/buriti-de-goias_goiás_5203939_r00_amaweb_t1_20260620_002559.pdf | U2: /media/serv-bot/cebece73-ca34-45fa-ba0e-9a1a1807e5c3/TCC_Unifal/Processamento_TCC_Unifal/sessoes/2026-06-20_00-25-00__validacao_tcc_unifal_r00/json/r00_5203939_49c814da.json | X2: 46193.018
A3: 2 | B3: r00 | C3: 2026-06-20_00-25-00__validacao_tcc_unifal_r00 | D3: 1200179 | E3: amaweb | F3: 1 | G3: https://www.capixaba.ac.gov.br/ | H3: https://amaweb.unifesp.br/avaliador/results/https%3A%2F%2Fwww.capixaba.ac.gov.br%2F | I3: amaweb.unifesp.br | J3: 1 | K3: AMAWeb | Avaliador | L3: 46193.018 | M3: 46193.018 | N3: 5481 | O3: sucesso | P3: 61 | Q3: 6.1 | R3: /media/serv-bot/cebece73-ca34-45fa-ba0e-9a1a1807e5c3/TCC_Unifal/Evidencias_TCC_Unifal/relatorios_ferramentas/2026-06-20_00-25-00__validacao_tcc_unifal_r00/amaweb/capixaba-acre-1200179/capixaba_acre_1200179_r00_amaweb_t1_20260620_002609.pdf | U3: /media/serv-bot/cebece73-ca34-45fa-ba0e-9a1a1807e5c3/TCC_Unifal/Processamento_TCC_Unifal/sessoes/2026-06-20_00-25-00__validacao_tcc_unifal_r00/json/r00_1200179_9cc651b6.json | X3: 46193.018
A4: 3 | B4: r00 | C4: 2026-06-20_00-25-00__validacao_tcc_unifal_r00 | D4: 5203939 | E4: accessmonitor | F4: 1 | G4: https://buritidegoias.go.gov.br/ | H4: https://buritidegoias.go.gov.br/ | I4: buritidegoias.go.gov.br | J4: 0 | K4: Prefeitura Municipal de Buriti de Goiás | L4: 46193.018 | M4: 46193.018 | N4: 1224 | O4: sucesso | P4: 72 | Q4: 7.2 | U4: /media/serv-bot/cebece73-ca34-45fa-ba0e-9a1a1807e5c3/TCC_Unifal/Evidencias_TCC_Unifal/relatorios_ferramentas/2026-06-20_00-25-00__validacao_tcc_unifal_r00/accessmonitor/buriti-de-goias-goias-5203939/buriti-de-goias_goiás_5203939_r00_accessmonitor_t1_20260620_002611.json | X4: 46193.018
A5: 4 | B5: r00 | C5: 2026-06-20_00-25-00__validacao_tcc_unifal_r00 | D5: 1200179 | E5: accessmonitor | F5: 1 | G5: https://www.capixaba.ac.gov.br/ | H5: https://www.capixaba.ac.gov.br/ | I5: www.capixaba.ac.gov.br | J5: 0 | K5: Prefeitura de Capixaba | L5: 46193.018 | M5: 46193.019 | N5: 2064 | O5: sucesso | P5: 61 | Q5: 6.1 | U5: /media/serv-bot/cebece73-ca34-45fa-ba0e-9a1a1807e5c3/TCC_Unifal/Evidencias_TCC_Unifal/relatorios_ferramentas/2026-06-20_00-25-00__validacao_tcc_unifal_r00/accessmonitor/capixaba-acre-1200179/capixaba_acre_1200179_r00_accessmonitor_t1_20260620_002620.json | X5: 46193.019
A6: 5 | B6: r00 | C6: 2026-06-20_00-25-00__validacao_tcc_unifal_r00 | D6: 5204656 | E6: amaweb | F6: 1 | G6: https://www.campinacu.go.gov.br/ | H6: https://amaweb.unifesp.br/avaliador/results/https%3A%2F%2Fwww.campinacu.go.gov.br%2F | I6: amaweb.unifesp.br | J6: 1 | K6: AMAWeb | Avaliador | L6: 46193.018 | M6: 46193.019 | N6: 4005 | O6: sucesso | P6: 69 | Q6: 6.9 | R6: /media/serv-bot/cebece73-ca34-45fa-ba0e-9a1a1807e5c3/TCC_Unifal/Evidencias_TCC_Unifal/relatorios_ferramentas/2026-06-20_00-25-00__validacao_tcc_unifal_r00/amaweb/campinacu-goias-5204656/campinacu_goiás_5204656_r00_amaweb_t1_20260620_002707.pdf | U6: /media/serv-bot/cebece73-ca34-45fa-ba0e-9a1a1807e5c3/TCC_Unifal/Processamento_TCC_Unifal/sessoes/2026-06-20_00-25-00__validacao_tcc_unifal_r00/json/r00_5204656_1a4a6b79.json | X6: 46193.019
A7: 6 | B7: r00 | C7: 2026-06-20_00-25-00__validacao_tcc_unifal_r00 | D7: 5204656 | E7: accessmonitor | F7: 1 | G7: https://www.campinacu.go.gov.br/ | H7: https://www.campinacu.go.gov.br/ | I7: www.campinacu.go.gov.br | J7: 0 | K7: Prefeitura de Campinaçu – Um novo tempo, uma nova história. | L7: 46193.019 | M7: 46193.019 | N7: 824 | O7: sucesso | P7: 69 | Q7: 6.9 | U7: /media/serv-bot/cebece73-ca34-45fa-ba0e-9a1a1807e5c3/TCC_Unifal/Evidencias_TCC_Unifal/relatorios_ferramentas/2026-06-20_00-25-00__validacao_tcc_unifal_r00/accessmonitor/campinacu-goias-5204656/campinacu_goiás_5204656_r00_accessmonitor_t1_20260620_002719.json | X7: 46193.019
A8: 7 | B8: r00 | C8: 2026-06-20_00-25-00__validacao_tcc_unifal_r00 | D8: 5205802 | E8: amaweb | F8: 1 | G8: https://corumbadegoias.go.gov.br/ | H8: https://amaweb.unifesp.br/avaliador/results/https%3A%2F%2Fcorumbadegoias.go.gov.br%2F | I8: amaweb.unifesp.br | J8: 1 | K8: AMAWeb | Avaliador | L8: 46193.019 | M8: 46193.019 | N8: 2654 | O8: sucesso | P8: 74 | Q8: 7.4 | R8: /media/serv-bot/cebece73-ca34-45fa-ba0e-9a1a1807e5c3/TCC_Unifal/Evidencias_TCC_Unifal/relatorios_ferramentas/2026-06-20_00-25-00__validacao_tcc_unifal_r00/amaweb/corumba-de-goias-goias-5205802/corumba-de-goias_goiás_5205802_r00_amaweb_t1_20260620_002757.pdf | U8: /media/serv-bot/cebece73-ca34-45fa-ba0e-9a1a1807e5c3/TCC_Unifal/Processamento_TCC_Unifal/sessoes/2026-06-20_00-25-00__validacao_tcc_unifal_r00/json/r00_5205802_7cf4a7a6.json | X8: 46193.019
A9: 8 | B9: r00 | C9: 2026-06-20_00-25-00__validacao_tcc_unifal_r00 | D9: 5205802 | E9: accessmonitor | F9: 1 | G9: https://corumbadegoias.go.gov.br/ | H9: https://corumbadegoias.go.gov.br/ | I9: corumbadegoias.go.gov.br | J9: 0 | K9: Prefeitura de Corumbá de Goiás | L9: 46193.02 | M9: 46193.02 | N9: 629 | O9: sucesso | P9: 74 | Q9: 7.4 | U9: /media/serv-bot/cebece73-ca34-45fa-ba0e-9a1a1807e5c3/TCC_Unifal/Evidencias_TCC_Unifal/relatorios_ferramentas/2026-06-20_00-25-00__validacao_tcc_unifal_r00/accessmonitor/corumba-de-goias-goias-5205802/corumba-de-goias_goiás_5205802_r00_accessmonitor_t1_20260620_002810.json | X9: 46193.02
A10: 9 | B10: r00 | C10: 2026-06-20_00-25-00__validacao_tcc_unifal_r00 | D10: 2700102 | E10: amaweb | F10: 1 | G10: https://aguabranca.al.gov.br/ | H10: https://amaweb.unifesp.br/avaliador/results/https%3A%2F%2Faguabranca.al.gov.br%2F | I10: amaweb.unifesp.br | J10: 1 | K10: AMAWeb | Avaliador | L10: 46193.018 | M10: 46193.02 | N10: 19283 | O10: falha_de_carregamento | R10: /media/serv-bot/cebece73-ca34-45fa-ba0e-9a1a1807e5c3/TCC_Unifal/Evidencias_TCC_Unifal/relatorios_ferramentas/2026-06-20_00-25-00__validacao_tcc_unifal_r00/amaweb/agua-branca-alagoas-2700102/agua-branca_alagoas_2700102_r00_amaweb_t1_20260620_002827.pdf | U10: /media/serv-bot/cebece73-ca34-45fa-ba0e-9a1a1807e5c3/TCC_Unifal/Processamento_TCC_Unifal/sessoes/2026-06-20_00-25-00__validacao_tcc_unifal_r00/json/r00_2700102_05d402b4.json | V10: falha_de_carregamento | X10: 46193.02
A11: 10 | B11: r00 | C11: 2026-06-20_00-25-00__validacao_tcc_unifal_r00 | D11: 2700102 | E11: amaweb | F11: 2 | G11: https://aguabranca.al.gov.br/ | H11: https://amaweb.unifesp.br/avaliador/results/https%3A%2F%2Faguabranca.al.gov.br%2F | I11: amaweb.unifesp.br | J11: 1 | K11: AMAWeb | Avaliador | L11: 46193.02 | M11: 46193.02 | N11: 824 | O11: sucesso | P11: 57 | Q11: 5.7 | R11: /media/serv-bot/cebece73-ca34-45fa-ba0e-9a1a1807e5c3/TCC_Unifal/Evidencias_TCC_Unifal/relatorios_ferramentas/2026-06-20_00-25-00__validacao_tcc_unifal_r00/amaweb/agua-branca-alagoas-2700102/agua-branca_alagoas_2700102_r00_amaweb_t2_20260620_002850.pdf | U11: /media/serv-bot/cebece73-ca34-45fa-ba0e-9a1a1807e5c3/TCC_Unifal/Processamento_TCC_Unifal/sessoes/2026-06-20_00-25-00__validacao_tcc_unifal_r00/json/r00_2700102_05d402b4.json | X11: 46193.02
A12: 11 | B12: r00 | C12: 2026-06-20_00-25-00__validacao_tcc_unifal_r00 | D12: 5206602 | E12: amaweb | F12: 1 | G12: https://cumari.go.gov.br/ | H12: https://amaweb.unifesp.br/avaliador/results/https%3A%2F%2Fcumari.go.gov.br%2F | I12: amaweb.unifesp.br | J12: 1 | K12: AMAWeb | Avaliador | L12: 46193.02 | M12: 46193.02 | N12: 3368 | O12: sucesso | P12: 70 | Q12: 7 | R12: /media/serv-bot/cebece73-ca34-45fa-ba0e-9a1a1807e5c3/TCC_Unifal/Evidencias_TCC_Unifal/relatorios_ferramentas/2026-06-20_00-25-00__validacao_tcc_unifal_r00/amaweb/cumari-goias-5206602/cumari_goiás_5206602_r00_amaweb_t1_20260620_002854.pdf | U12: /media/serv-bot/cebece73-ca34-45fa-ba0e-9a1a1807e5c3/TCC_Unifal/Processamento_TCC_Unifal/sessoes/2026-06-20_00-25-00__validacao_tcc_unifal_r00/json/r00_5206602_cc2e0a52.json | X12: 46193.02
A13: 12 | B13: r00 | C13: 2026-06-20_00-25-00__validacao_tcc_unifal_r00 | D13: 2700102 | E13: accessmonitor | F13: 1 | G13: https://aguabranca.al.gov.br/ | H13: https://aguabranca.al.gov.br/ | I13: aguabranca.al.gov.br | J13: 0 | K13: Prefeitura - Água Branca | L13: 46193.02 | M13: 46193.02 | N13: 1147 | O13: sucesso_sem_nota | U13: /media/serv-bot/cebece73-ca34-45fa-ba0e-9a1a1807e5c3/TCC_Unifal/Evidencias_TCC_Unifal/relatorios_ferramentas/2026-06-20_00-25-00__validacao_tcc_unifal_r00/accessmonitor/agua-branca-alagoas-2700102/agua-branca_alagoas_2700102_r00_accessmonitor_t1_20260620_002903.json | X13: 46193.02
A14: 13 | B14: r00 | C14: 2026-06-20_00-25-00__validacao_tcc_unifal_r00 | D14: 5206602 | E14: accessmonitor | F14: 1 | G14: https://cumari.go.gov.br/ | H14: https://cumari.go.gov.br/ | I14: cumari.go.gov.br | J14: 0 | K14: Prefeitura Municipal de Cumari | L14: 46193.02 | M14: 46193.02 | N14: 1224 | O14: sucesso | P14: 69 | Q14: 6.9 | U14: /media/serv-bot/cebece73-ca34-45fa-ba0e-9a1a1807e5c3/TCC_Unifal/Evidencias_TCC_Unifal/relatorios_ferramentas/2026-06-20_00-25-00__validacao_tcc_unifal_r00/accessmonitor/cumari-goias-5206602/cumari_goiás_5206602_r00_accessmonitor_t1_20260620_002906.json | X14: 46193.02
A15: 14 | B15: r00 | C15: 2026-06-20_00-25-00__validacao_tcc_unifal_r00 | D15: 2700102 | E15: accessmonitor | F15: 2 | G15: https://aguabranca.al.gov.br/ | H15: https://aguabranca.al.gov.br/ | I15: aguabranca.al.gov.br | J15: 0 | K15: Prefeitura - Água Branca | L15: 46193.02 | M15: 46193.021 | N15: 1108 | O15: sucesso_sem_nota | U15: /media/serv-bot/cebece73-ca34-45fa-ba0e-9a1a1807e5c3/TCC_Unifal/Evidencias_TCC_Unifal/relatorios_ferramentas/2026-06-20_00-25-00__validacao_tcc_unifal_r00/accessmonitor/agua-branca-alagoas-2700102/agua-branca_alagoas_2700102_r00_accessmonitor_t2_20260620_002925.json | X15: 46193.021
A16: 15 | B16: r00 | C16: 2026-06-20_00-25-00__validacao_tcc_unifal_r00 | D16: 1200393 | E16: amaweb | F16: 1 | G16: https://www.portowalter.ac.gov.br/ | H16: https://amaweb.unifesp.br/avaliador/results/https%3A%2F%2Fwww.portowalter.ac.gov.br%2F | I16: amaweb.unifesp.br | J16: 1 | K16: AMAWeb | Avaliador | L16: 46193.019 | M16: 46193.021 | N16: 18700 | O16: falha_de_carregamento | R16: /media/serv-bot/cebece73-ca34-45fa-ba0e-9a1a1807e5c3/TCC_Unifal/Evidencias_TCC_Unifal/relatorios_ferramentas/2026-06-20_00-25-00__validacao_tcc_unifal_r00/amaweb/porto-walter-acre-1200393/porto-walter_acre_1200393_r00_amaweb_t1_20260620_002951.pdf | U16: /media/serv-bot/cebece73-ca34-45fa-ba0e-9a1a1807e5c3/TCC_Unifal/Processamento_TCC_Unifal/sessoes/2026-06-20_00-25-00__validacao_tcc_unifal_r00/json/r00_1200393_363ff175.json | V16: falha_de_carregamento | X16: 46193.021
A17: 16 | B17: r00 | C17: 2026-06-20_00-25-00__validacao_tcc_unifal_r00 | D17: 5207253 | E17: amaweb | F17: 1 | G17: https://doverlandia.go.gov.br/ | H17: https://amaweb.unifesp.br/avaliador/results/https%3A%2F%2Fdoverlandia.go.gov.br%2F | I17: amaweb.unifesp.br | J17: 1 | K17: AMAWeb | Avaliador | L17: 46193.02 | M17: 46193.021 | N17: 3030 | O17: sucesso | P17: 76 | Q17: 7.6 | R17: /media/serv-bot/cebece73-ca34-45fa-ba0e-9a1a1807e5c3/TCC_Unifal/Evidencias_TCC_Unifal/relatorios_ferramentas/2026-06-20_00-25-00__validacao_tcc_unifal_r00/amaweb/doverlandia-goias-5207253/doverlandia_goiás_5207253_r00_amaweb_t1_20260620_002952.pdf | U17: /media/serv-bot/cebece73-ca34-45fa-ba0e-9a1a1807e5c3/TCC_Unifal/Processamento_TCC_Unifal/sessoes/2026-06-20_00-25-00__validacao_tcc_unifal_r00/json/r00_5207253_0b053355.json | X17: 46193.021
A18: 17 | B18: r00 | C18: 2026-06-20_00-25-00__validacao_tcc_unifal_r00 | D18: 2700102 | E18: accessmonitor | F18: 3 | G18: https://aguabranca.al.gov.br/ | H18: https://aguabranca.al.gov.br/ | I18: aguabranca.al.gov.br | J18: 0 | K18: Prefeitura - Água Branca | L18: 46193.021 | M18: 46193.021 | N18: 1122 | O18: sucesso_sem_nota | U18: /media/serv-bot/cebece73-ca34-45fa-ba0e-9a1a1807e5c3/TCC_Unifal/Evidencias_TCC_Unifal/relatorios_ferramentas/2026-06-20_00-25-00__validacao_tcc_unifal_r00/accessmonitor/agua-branca-alagoas-2700102/agua-branca_alagoas_2700102_r00_accessmonitor_t3_20260620_002955.json | X18: 46193.021
A19: 18 | B19: r00 | C19: 2026-06-20_00-25-00__validacao_tcc_unifal_r00 | D19: 5207253 | E19: accessmonitor | F19: 1 | G19: https://doverlandia.go.gov.br/ | H19: https://doverlandia.go.gov.br/ | I19: doverlandia.go.gov.br | J19: 0 | K19: Prefeitura de Doverlândia | L19: 46193.021 | M19: 46193.021 | N19: 586 | O19: sucesso | P19: 78 | Q19: 7.8 | U19: /media/serv-bot/cebece73-ca34-45fa-ba0e-9a1a1807e5c3/TCC_Unifal/Evidencias_TCC_Unifal/relatorios_ferramentas/2026-06-20_00-25-00__validacao_tcc_unifal_r00/accessmonitor/doverlandia-goias-5207253/doverlandia_goiás_5207253_r00_accessmonitor_t1_20260620_003005.json | X19: 46193.021
A20: 19 | B20: r00 | C20: 2026-06-20_00-25-00__validacao_tcc_unifal_r00 | D20: 2702207 | E20: amaweb | F20: 1 | G20: https://coqueiroseco.al.gov.br/ | H20: https://amaweb.unifesp.br/avaliador/results/https%3A%2F%2Fcoqueiroseco.al.gov.br%2F | I20: amaweb.unifesp.br | J20: 1 | K20: AMAWeb | Avaliador | L20: 46193.021 | M20: 46193.021 | N20: 1870 | O20: sucesso | P20: 54 | Q20: 5.4 | R20: /media/serv-bot/cebece73-ca34-45fa-ba0e-9a1a1807e5c3/TCC_Unifal/Evidencias_TCC_Unifal/relatorios_ferramentas/2026-06-20_00-25-00__validacao_tcc_unifal_r00/amaweb/coqueiro-seco-alagoas-2702207/coqueiro-seco_alagoas_2702207_r00_amaweb_t1_20260620_003029.pdf | U20: /media/serv-bot/cebece73-ca34-45fa-ba0e-9a1a1807e5c3/TCC_Unifal/Processamento_TCC_Unifal/sessoes/2026-06-20_00-25-00__validacao_tcc_unifal_r00/json/r00_2702207_71b8a360.json | X20: 46193.021
A21: 20 | B21: r00 | C21: 2026-06-20_00-25-00__validacao_tcc_unifal_r00 | D21: 5208806 | E21: amaweb | F21: 1 | G21: https://goianira.go.gov.br/ | H21: https://amaweb.unifesp.br/avaliador/results/https%3A%2F%2Fgoianira.go.gov.br%2F | I21: amaweb.unifesp.br | J21: 1 | K21: AMAWeb | Avaliador | L21: 46193.021 | M21: 46193.021 | N21: 3289 | O21: sucesso | P21: 70 | Q21: 7 | R21: /media/serv-bot/cebece73-ca34-45fa-ba0e-9a1a1807e5c3/TCC_Unifal/Evidencias_TCC_Unifal/relatorios_ferramentas/2026-06-20_00-25-00__validacao_tcc_unifal_r00/amaweb/goianira-goias-5208806/goianira_goiás_5208806_r00_amaweb_t1_20260620_003049.pdf | U21: /media/serv-bot/cebece73-ca34-45fa-ba0e-9a1a1807e5c3/TCC_Unifal/Processamento_TCC_Unifal/sessoes/2026-06-20_00-25-00__validacao_tcc_unifal_r00/json/r00_5208806_d034b0c6.json | X21: 46193.021
A22: 21 | B22: r00 | C22: 2026-06-20_00-25-00__validacao_tcc_unifal_r00 | D22: 2702207 | E22: accessmonitor | F22: 1 | G22: https://coqueiroseco.al.gov.br/ | H22: https://coqueiroseco.al.gov.br/ | I22: coqueiroseco.al.gov.br | J22: 0 | K22: Prefeitura de Coqueiro Seco | L22: 46193.021 | M22: 46193.021 | N22: 958 | O22: sucesso | P22: 58 | Q22: 5.8 | U22: /media/serv-bot/cebece73-ca34-45fa-ba0e-9a1a1807e5c3/TCC_Unifal/Evidencias_TCC_Unifal/relatorios_ferramentas/2026-06-20_00-25-00__validacao_tcc_unifal_r00/accessmonitor/coqueiro-seco-alagoas-2702207/coqueiro-seco_alagoas_2702207_r00_accessmonitor_t1_20260620_003042.json | X22: 46193.021
A23: 22 | B23: r00 | C23: 2026-06-20_00-25-00__validacao_tcc_unifal_r00 | D23: 1200393 | E23: amaweb | F23: 2 | G23: https://www.portowalter.ac.gov.br/ | H23: https://amaweb.unifesp.br/avaliador/results/https%3A%2F%2Fwww.portowalter.ac.gov.br%2F | I23: amaweb.unifesp.br | J23: 1 | K23: AMAWeb | Avaliador | L23: 46193.021 | M23: 46193.021 | N23: 4274 | O23: sucesso | P23: 61 | Q23: 6.1 | R23: /media/serv-bot/cebece73-ca34-45fa-ba0e-9a1a1807e5c3/TCC_Unifal/Evidencias_TCC_Unifal/relatorios_ferramentas/2026-06-20_00-25-00__validacao_tcc_unifal_r00/amaweb/porto-walter-acre-1200393/porto-walter_acre_1200393_r00_amaweb_t2_20260620_003054.pdf | U23: /media/serv-bot/cebece73-ca34-45fa-ba0e-9a1a1807e5c3/TCC_Unifal/Processamento_TCC_Unifal/sessoes/2026-06-20_00-25-00__validacao_tcc_unifal_r00/json/r00_1200393_363ff175.json | X23: 46193.021
A24: 23 | B24: r00 | C24: 2026-06-20_00-25-00__validacao_tcc_unifal_r00 | D24: 5208806 | E24: accessmonitor | F24: 1 | G24: https://goianira.go.gov.br/ | H24: https://goianira.go.gov.br/ | I24: goianira.go.gov.br | J24: 0 | K24: Prefeitura de Goianira - Acesse informações sobre receitas, gastos em serviços públicos, investimentos. | L24: 46193.022 | M24: 46193.022 | N24: 999 | O24: sucesso | P24: 72 | Q24: 7.2 | U24: /media/serv-bot/cebece73-ca34-45fa-ba0e-9a1a1807e5c3/TCC_Unifal/Evidencias_TCC_Unifal/relatorios_ferramentas/2026-06-20_00-25-00__validacao_tcc_unifal_r00/accessmonitor/goianira-goias-5208806/goianira_goiás_5208806_r00_accessmonitor_t1_20260620_003100.json | X24: 46193.022
A25: 24 | B25: r00 | C25: 2026-06-20_00-25-00__validacao_tcc_unifal_r00 | D25: 1200393 | E25: accessmonitor | F25: 1 | G25: https://www.portowalter.ac.gov.br/ | H25: https://www.portowalter.ac.gov.br/ | I25: www.portowalter.ac.gov.br | J25: 0 | K25: Prefeitura de Porto Walter | L25: 46193.022 | M25: 46193.022 | N25: 2704 | O25: sucesso | P25: 61 | Q25: 6.1 | U25: /media/serv-bot/cebece73-ca34-45fa-ba0e-9a1a1807e5c3/TCC_Unifal/Evidencias_TCC_Unifal/relatorios_ferramentas/2026-06-20_00-25-00__validacao_tcc_unifal_r00/accessmonitor/porto-walter-acre-1200393/porto-walter_acre_1200393_r00_accessmonitor_t1_20260620_003106.json | X25: 46193.022
A26: 25 | B26: r00 | C26: 2026-06-20_00-25-00__validacao_tcc_unifal_r00 | D26: 2702900 | E26: amaweb | F26: 1 | G26: https://giraudoponciano.al.gov.br/ | H26: https://amaweb.unifesp.br/avaliador/results/https%3A%2F%2Fgiraudoponciano.al.gov.br%2F | I26: amaweb.unifesp.br | J26: 1 | K26: AMAWeb | Avaliador | L26: 46193.021 | M26: 46193.022 | N26: 3913 | O26: sucesso | P26: 64 | Q26: 6.4 | R26: /media/serv-bot/cebece73-ca34-45fa-ba0e-9a1a1807e5c3/TCC_Unifal/Evidencias_TCC_Unifal/relatorios_ferramentas/2026-06-20_00-25-00__validacao_tcc_unifal_r00/amaweb/girau-do-ponciano-alagoas-2702900/girau-do-ponciano_alagoas_2702900_r00_amaweb_t1_20260620_003134.pdf | U26: /media/serv-bot/cebece73-ca34-45fa-ba0e-9a1a1807e5c3/TCC_Unifal/Processamento_TCC_Unifal/sessoes/2026-06-20_00-25-00__validacao_tcc_unifal_r00/json/r00_2702900_392785d8.json | X26: 46193.022
A27: 26 | B27: r00 | C27: 2026-06-20_00-25-00__validacao_tcc_unifal_r00 | D27: 5209457 | E27: amaweb | F27: 1 | G27: https://guarinos.go.gov.br/ | H27: https://amaweb.unifesp.br/avaliador/results/https%3A%2F%2Fguarinos.go.gov.br%2F | I27: amaweb.unifesp.br | J27: 1 | K27: AMAWeb | Avaliador | L27: 46193.022 | M27: 46193.022 | N27: 3245 | O27: sucesso | P27: 73 | Q27: 7.3 | R27: /media/serv-bot/cebece73-ca34-45fa-ba0e-9a1a1807e5c3/TCC_Unifal/Evidencias_TCC_Unifal/relatorios_ferramentas/2026-06-20_00-25-00__validacao_tcc_unifal_r00/amaweb/guarinos-goias-5209457/guarinos_goiás_5209457_r00_amaweb_t1_20260620_003147.pdf | U27: /media/serv-bot/cebece73-ca34-45fa-ba0e-9a1a1807e5c3/TCC_Unifal/Processamento_TCC_Unifal/sessoes/2026-06-20_00-25-00__validacao_tcc_unifal_r00/json/r00_5209457_5902cc66.json | X27: 46193.022
A28: 27 | B28: r00 | C28: 2026-06-20_00-25-00__validacao_tcc_unifal_r00 | D28: 1600303 | E28: amaweb | F28: 1 | G28: https://www.macapa.ap.gov.br/ | H28: https://amaweb.unifesp.br/avaliador/results/https%3A%2F%2Fwww.macapa.ap.gov.br%2F | I28: amaweb.unifesp.br | J28: 1 | K28: AMAWeb | Avaliador | L28: 46193.022 | M28: 46193.022 | N28: 1263 | O28: sucesso | P28: 92 | Q28: 9.2 | R28: /media/serv-bot/cebece73-ca34-45fa-ba0e-9a1a1807e5c3/TCC_Unifal/Evidencias_TCC_Unifal/relatorios_ferramentas/2026-06-20_00-25-00__validacao_tcc_unifal_r00/amaweb/macapa-amapa-1600303/macapa_amapá_1600303_r00_amaweb_t1_20260620_003149.pdf | U28: /media/serv-bot/cebece73-ca34-45fa-ba0e-9a1a1807e5c3/TCC_Unifal/Processamento_TCC_Unifal/sessoes/2026-06-20_00-25-00__validacao_tcc_unifal_r00/json/r00_1600303_f7a8ad76.json | X28: 46193.022
A29: 28 | B29: r00 | C29: 2026-06-20_00-25-00__validacao_tcc_unifal_r00 | D29: 2702900 | E29: accessmonitor | F29: 1 | G29: https://giraudoponciano.al.gov.br/ | H29: https://giraudoponciano.al.gov.br/ | I29: giraudoponciano.al.gov.br | J29: 0 | K29: Home - Girau do Ponciano | L29: 46193.022 | M29: 46193.022 | N29: 845 | O29: sucesso | P29: 68 | Q29: 6.8 | U29: /media/serv-bot/cebece73-ca34-45fa-ba0e-9a1a1807e5c3/TCC_Unifal/Evidencias_TCC_Unifal/relatorios_ferramentas/2026-06-20_00-25-00__validacao_tcc_unifal_r00/accessmonitor/girau-do-ponciano-alagoas-2702900/girau-do-ponciano_alagoas_2702900_r00_accessmonitor_t1_20260620_003147.json | X29: 46193.022
A30: 29 | B30: r00 | C30: 2026-06-20_00-25-00__validacao_tcc_unifal_r00 | D30: 5209457 | E30: accessmonitor | F30: 1 | G30: https://guarinos.go.gov.br/ | H30: https://guarinos.go.gov.br/ | I30: guarinos.go.gov.br | J30: 0 | K30: Prefeitura Municipal de Guarinos | L30: 46193.022 | M30: 46193.022 | N30: 655 | O30: sucesso | P30: 72 | Q30: 7.2 | U30: /media/serv-bot/cebece73-ca34-45fa-ba0e-9a1a1807e5c3/TCC_Unifal/Evidencias_TCC_Unifal/relatorios_ferramentas/2026-06-20_00-25-00__validacao_tcc_unifal_r00/accessmonitor/guarinos-goias-5209457/guarinos_goiás_5209457_r00_accessmonitor_t1_20260620_003200.json | X30: 46193.022
A31: 30 | B31: r00 | C31: 2026-06-20_00-25-00__validacao_tcc_unifal_r00 | D31: 1600303 | E31: accessmonitor | F31: 1 | G31: https://www.macapa.ap.gov.br/ | H31: https://macapa.ap.gov.br/ | I31: macapa.ap.gov.br | J31: 1 | K31: Home - Prefeitura Municipal de Macapá | L31: 46193.022 | M31: 46193.023 | N31: 2664 | O31: sucesso_sem_nota | U31: /media/serv-bot/cebece73-ca34-45fa-ba0e-9a1a1807e5c3/TCC_Unifal/Evidencias_TCC_Unifal/relatorios_ferramentas/2026-06-20_00-25-00__validacao_tcc_unifal_r00/accessmonitor/macapa-amapa-1600303/macapa_amapá_1600303_r00_accessmonitor_t1_20260620_003200.json | X31: 46193.023
A32: 31 | B32: r00 | C32: 2026-06-20_00-25-00__validacao_tcc_unifal_r00 | D32: 2703304 | E32: amaweb | F32: 1 | G32: https://inhapi.al.gov.br/ | H32: https://amaweb.unifesp.br/avaliador/results/https%3A%2F%2Finhapi.al.gov.br%2F | I32: amaweb.unifesp.br | J32: 1 | K32: AMAWeb | Avaliador | L32: 46193.022 | M32: 46193.023 | N32: 3044 | O32: sucesso | P32: 64 | Q32: 6.4 | R32: /media/serv-bot/cebece73-ca34-45fa-ba0e-9a1a1807e5c3/TCC_Unifal/Evidencias_TCC_Unifal/relatorios_ferramentas/2026-06-20_00-25-00__validacao_tcc_unifal_r00/amaweb/inhapi-alagoas-2703304/inhapi_alagoas_2703304_r00_amaweb_t1_20260620_003229.pdf | U32: /media/serv-bot/cebece73-ca34-45fa-ba0e-9a1a1807e5c3/TCC_Unifal/Processamento_TCC_Unifal/sessoes/2026-06-20_00-25-00__validacao_tcc_unifal_r00/json/r00_2703304_fd39433c.json | X32: 46193.023
A33: 32 | B33: r00 | C33: 2026-06-20_00-25-00__validacao_tcc_unifal_r00 | D33: 5210802 | E33: amaweb | F33: 1 | G33: https://itaja.go.gov.br/ | H33: https://amaweb.unifesp.br/avaliador/results/https%3A%2F%2Fitaja.go.gov.br%2F | I33: amaweb.unifesp.br | J33: 1 | K33: AMAWeb | Avaliador | L33: 46193.022 | M33: 46193.023 | N33: 3694 | O33: sucesso | P33: 63 | Q33: 6.3 | R33: /media/serv-bot/cebece73-ca34-45fa-ba0e-9a1a1807e5c3/TCC_Unifal/Evidencias_TCC_Unifal/relatorios_ferramentas/2026-06-20_00-25-00__validacao_tcc_unifal_r00/amaweb/itaja-goias-5210802/itaja_goiás_5210802_r00_amaweb_t1_20260620_003248.pdf | U33: /media/serv-bot/cebece73-ca34-45fa-ba0e-9a1a1807e5c3/TCC_Unifal/Processamento_TCC_Unifal/sessoes/2026-06-20_00-25-00__validacao_tcc_unifal_r00/json/r00_5210802_8407d26c.json | X33: 46193.023
A34: 33 | B34: r00 | C34: 2026-06-20_00-25-00__validacao_tcc_unifal_r00 | D34: 1600303 | E34: accessmonitor | F34: 2 | G34: https://www.macapa.ap.gov.br/ | H34: https://macapa.ap.gov.br/ | I34: macapa.ap.gov.br | J34: 1 | K34: Home - Prefeitura Municipal de Macapá | L34: 46193.023 | M34: 46193.023 | N34: 1167 | O34: sucesso_sem_nota | U34: /media/serv-bot/cebece73-ca34-45fa-ba0e-9a1a1807e5c3/TCC_Unifal/Evidencias_TCC_Unifal/relatorios_ferramentas/2026-06-20_00-25-00__validacao_tcc_unifal_r00/accessmonitor/macapa-amapa-1600303/macapa_amapá_1600303_r00_accessmonitor_t2_20260620_003237.json | X34: 46193.023
A35: 34 | B35: r00 | C35: 2026-06-20_00-25-00__validacao_tcc_unifal_r00 | D35: 2703304 | E35: accessmonitor | F35: 1 | G35: https://inhapi.al.gov.br/ | H35: https://inhapi.al.gov.br/ | I35: inhapi.al.gov.br | J35: 0 | K35: BEM - VINDO - Prefeitura de Inhapi | L35: 46193.023 | M35: 46193.023 | N35: 1011 | O35: sucesso | P35: 60 | Q35: 6 | U35: /media/serv-bot/cebece73-ca34-45fa-ba0e-9a1a1807e5c3/TCC_Unifal/Evidencias_TCC_Unifal/relatorios_ferramentas/2026-06-20_00-25-00__validacao_tcc_unifal_r00/accessmonitor/inhapi-alagoas-2703304/inhapi_alagoas_2703304_r00_accessmonitor_t1_20260620_003241.json | X35: 46193.023
A36: 35 | B36: r00 | C36: 2026-06-20_00-25-00__validacao_tcc_unifal_r00 | D36: 5210802 | E36: accessmonitor | F36: 1 | G36: https://itaja.go.gov.br/ | H36: https://itaja.go.gov.br/ | I36: itaja.go.gov.br | J36: 0 | K36: Prefeitura Municipal de Itajá | L36: 46193.023 | M36: 46193.023 | N36: 733 | O36: sucesso | P36: 62 | Q36: 6.2 | U36: /media/serv-bot/cebece73-ca34-45fa-ba0e-9a1a1807e5c3/TCC_Unifal/Evidencias_TCC_Unifal/relatorios_ferramentas/2026-06-20_00-25-00__validacao_tcc_unifal_r00/accessmonitor/itaja-goias-5210802/itaja_goiás_5210802_r00_accessmonitor_t1_20260620_003300.json | X36: 46193.023
A37: 36 | B37: r00 | C37: 2026-06-20_00-25-00__validacao_tcc_unifal_r00 | D37: 1600303 | E37: accessmonitor | F37: 3 | G37: https://www.macapa.ap.gov.br/ | H37: https://macapa.ap.gov.br/ | I37: macapa.ap.gov.br | J37: 1 | K37: Home - Prefeitura Municipal de Macapá | L37: 46193.023 | M37: 46193.023 | N37: 1198 | O37: sucesso_sem_nota | U37: /media/serv-bot/cebece73-ca34-45fa-ba0e-9a1a1807e5c3/TCC_Unifal/Evidencias_TCC_Unifal/relatorios_ferramentas/2026-06-20_00-25-00__validacao_tcc_unifal_r00/accessmonitor/macapa-amapa-1600303/macapa_amapá_1600303_r00_accessmonitor_t3_20260620_003309.json | X37: 46193.023
A38: 37 | B38: r00 | C38: 2026-06-20_00-25-00__validacao_tcc_unifal_r00 | D38: 2706422 | E38: amaweb | F38: 1 | G38: https://pariconha.al.gov.br/ | H38: https://amaweb.unifesp.br/avaliador/results/https%3A%2F%2Fpariconha.al.gov.br%2F | I38: amaweb.unifesp.br | J38: 1 | K38: AMAWeb | Avaliador | L38: 46193.023 | M38: 46193.023 | N38: 2616 | O38: sucesso | P38: 58 | Q38: 5.8 | R38: /media/serv-bot/cebece73-ca34-45fa-ba0e-9a1a1807e5c3/TCC_Unifal/Evidencias_TCC_Unifal/relatorios_ferramentas/2026-06-20_00-25-00__validacao_tcc_unifal_r00/amaweb/pariconha-alagoas-2706422/pariconha_alagoas_2706422_r00_amaweb_t1_20260620_003320.pdf | U38: /media/serv-bot/cebece73-ca34-45fa-ba0e-9a1a1807e5c3/TCC_Unifal/Processamento_TCC_Unifal/sessoes/2026-06-20_00-25-00__validacao_tcc_unifal_r00/json/r00_2706422_b775a631.json | X38: 46193.023
A39: 38 | B39: r00 | C39: 2026-06-20_00-25-00__validacao_tcc_unifal_r00 | D39: 5211800 | E39: amaweb | F39: 1 | G39: https://jaragua.go.gov.br/ | H39: https://amaweb.unifesp.br/avaliador/results/https%3A%2F%2Fjaragua.go.gov.br%2F | I39: amaweb.unifesp.br | J39: 1 | K39: AMAWeb | Avaliador | L39: 46193.023 | M39: 46193.023 | N39: 2789 | O39: sucesso | P39: 70 | Q39: 7 | R39: /media/serv-bot/cebece73-ca34-45fa-ba0e-9a1a1807e5c3/TCC_Unifal/Evidencias_TCC_Unifal/relatorios_ferramentas/2026-06-20_00-25-00__validacao_tcc_unifal_r00/amaweb/jaragua-goias-5211800/jaragua_goiás_5211800_r00_amaweb_t1_20260620_003339.pdf | U39: /media/serv-bot/cebece73-ca34-45fa-ba0e-9a1a1807e5c3/TCC_Unifal/Processamento_TCC_Unifal/sessoes/2026-06-20_00-25-00__validacao_tcc_unifal_r00/json/r00_5211800_dd51de7e.json | X39: 46193.023
A40: 39 | B40: r00 | C40: 2026-06-20_00-25-00__validacao_tcc_unifal_r00 | D40: 2706422 | E40: accessmonitor | F40: 1 | G40: https://pariconha.al.gov.br/ | H40: https://pariconha.al.gov.br/ | I40: pariconha.al.gov.br | J40: 0 | K40: Prefeitura de Pariconha – Alagoas – O novo jeito de governar | L40: 46193.023 | M40: 46193.023 | N40: 987 | O40: sucesso | P40: 57 | Q40: 5.7 | U40: /media/serv-bot/cebece73-ca34-45fa-ba0e-9a1a1807e5c3/TCC_Unifal/Evidencias_TCC_Unifal/relatorios_ferramentas/2026-06-20_00-25-00__validacao_tcc_unifal_r00/accessmonitor/pariconha-alagoas-2706422/pariconha_alagoas_2706422_r00_accessmonitor_t1_20260620_003332.json | X40: 46193.023
...

Sheet 00_Conferencia
A1: Indicador | B1: Resultado | D1: Rodada | E1: Registros
A2: Municípios na base | B2: =COUNTA(Base_Amostral!A:A)-1 -> 362 | D2: r00 | E2: =COUNTIF(Execucoes!B:B,D2) -> 362
A3: Códigos IBGE únicos | B3: {=SUMPRODUCT(1/COUNTIF(Base_Amostral!A2:A363,Base_Amostral!A2:A363))} -> 362 | D3: r01 | E3: =COUNTIF(Execucoes!B:B,D3) -> 362
A4: Registros de execução | B4: =COUNTA(Execucoes!A:A)-1 -> 1810 | D4: r02 | E4: =COUNTIF(Execucoes!B:B,D4) -> 362
A5: Rodadas esperadas | B5: 5 | D5: r03 | E5: =COUNTIF(Execucoes!B:B,D5) -> 362
A6: Registros esperados | B6: =B2*B5 -> 1810 | D6: r04 | E6: =COUNTIF(Execucoes!B:B,D6) -> 362
A7: Municípios por rodada | B7: =B4/B5 -> 362
A8: Duplicidades município + rodada | B8: {=COUNTA(Execucoes!Q2:Q1811)-SUMPRODUCT(1/COUNTIF(Execucoes!Q2:Q1811,Execucoes!Q2:Q1811))} -> 0
A10: Rodada | B10: AMA válidas | C10: Access válidas | D10: Pares válidos
A11: r00 | B11: =COUNTIFS(Execucoes!B:B,A11,Execucoes!K:K,1) -> 355 | C11: =COUNTIFS(Execucoes!B:B,A11,Execucoes!L:L,1) -> 354 | D11: =COUNTIFS(Execucoes!B:B,A11,Execucoes!K:K,1,Execucoes!L:L,1) -> 350
A12: r01 | B12: =COUNTIFS(Execucoes!B:B,A12,Execucoes!K:K,1) -> 356 | C12: =COUNTIFS(Execucoes!B:B,A12,Execucoes!L:L,1) -> 355 | D12: =COUNTIFS(Execucoes!B:B,A12,Execucoes!K:K,1,Execucoes!L:L,1) -> 351
A13: r02 | B13: =COUNTIFS(Execucoes!B:B,A13,Execucoes!K:K,1) -> 355 | C13: =COUNTIFS(Execucoes!B:B,A13,Execucoes!L:L,1) -> 354 | D13: =COUNTIFS(Execucoes!B:B,A13,Execucoes!K:K,1,Execucoes!L:L,1) -> 350
A14: r03 | B14: =COUNTIFS(Execucoes!B:B,A14,Execucoes!K:K,1) -> 355 | C14: =COUNTIFS(Execucoes!B:B,A14,Execucoes!L:L,1) -> 355 | D14: =COUNTIFS(Execucoes!B:B,A14,Execucoes!K:K,1,Execucoes!L:L,1) -> 351
A15: r04 | B15: =COUNTIFS(Execucoes!B:B,A15,Execucoes!K:K,1) -> 357 | C15: =COUNTIFS(Execucoes!B:B,A15,Execucoes!L:L,1) -> 354 | D15: =COUNTIFS(Execucoes!B:B,A15,Execucoes!K:K,1,Execucoes!L:L,1) -> 350
B16: =SUM(B12:B15) -> 1423 | C16: =SUM(C12:C15) -> 1418 | D16: =SUM(D12:D15) -> 1402
A18: Notas AMAWeb na base analítica | B18: =COUNT('01_Base_Analitica'!U2:U1449) -> 1423
A19: Notas AccessMonitor na base analítica | B19: =COUNT('01_Base_Analitica'!V2:V1449) -> 1418
A20: Pares válidos na base analítica | B20: =SUM('01_Base_Analitica'!Y2:Y1449) -> 1402

Sheet 01_Base_Analitica
A1: id_execucao | B1: rodada | C1: sessao | D1: codigo_municipio_completo | E1: nota_amaweb | F1: status_amaweb | G1: avaliado_amaweb_em | H1: nota_accessmonitor | I1: status_accessmonitor | J1: avaliado_accessmonitor_em | K1: tem_resultado_amaweb | L1: tem_resultado_accessmonitor | M1: status_geral | N1: observacao_analise | O1: criado_em | P1: atualizado_em | Q1: chave_municipio_rodada | R1: município | S1: UF | T1: região | U1: nota AMAWeb convertida | V1: nota AccessMonitor convertida | W1: diferença AMA − Access | X1: média das duas ferramentas | Y1: par válido | Z1: variação AMA rodada anterior | AA1: variação Access rodada anterior | AB1: amplitude AMA | AC1: amplitude Access | AD1: número de rodadas válidas AMA | AE1: número de rodadas válidas Access
A2: 429 | B2: r01 | C2: 2026-06-22_23-12-00__validacao_tcc_unifal_r01 | D2: 1100015 | E2: 70 | F2: sucesso | G2: 46195.995 | H2: 72 | I2: sucesso | J2: 46195.995 | K2: 1 | L2: 1 | M2: completo | O2: 46195.995 | P2: 46195.995 | Q2: =D2&"|"&B2 -> 1100015|r01 | R2: =VLOOKUP(D2,Base_Amostral!$A:$G,5,FALSE) -> Alta Floresta D'Oeste | S2: =VLOOKUP(D2,Base_Amostral!$A:$G,3,FALSE) -> Rondônia | T2: =VLOOKUP(D2,Base_Amostral!$A:$G,6,FALSE) -> Norte | U2: =IF(E2="","",E2/10) -> 7 | V2: =IF(H2="","",H2/10) -> 7.2 | W2: =IF(OR(U2="",V2=""),"",U2-V2) -> -0.2 | X2: =IF(OR(U2="",V2=""),"",AVERAGE(U2:V2)) -> 7.1 | Y2: =IF(AND(U2<>"",V2<>""),1,0) -> 1 | Z2: =IF(D2<>D1,"",IF(OR(U2="",U1=""),"",U2-U1)) | AA2: =IF(D2<>D1,"",IF(OR(V2="",V1=""),"",V2-V1)) | AB2: =IF(B2<>"r04","",IF(COUNT(INDEX(U:U,ROW()-3):U2)<2,"",MAX(INDEX(U:U,ROW()-3):U2)-MIN(INDEX(U:U,ROW()-3):U2))) | AC2: =IF(B2<>"r04","",IF(COUNT(INDEX(V:V,ROW()-3):V2)<2,"",MAX(INDEX(V:V,ROW()-3):V2)-MIN(INDEX(V:V,ROW()-3):V2))) | AD2: =IF(B2<>"r04","",COUNT(INDEX(U:U,ROW()-3):U2)) | AE2: =IF(B2<>"r04","",COUNT(INDEX(V:V,ROW()-3):V2))
A3: 775 | B3: r02 | C3: 2026-06-30_18-34-12__validacao_tcc_unifal_r02 | D3: 1100015 | E3: 70 | F3: sucesso | G3: 46203.794 | H3: 72 | I3: sucesso | J3: 46203.794 | K3: 1 | L3: 1 | M3: completo | O3: 46203.794 | P3: 46203.794 | Q3: =D3&"|"&B3 -> 1100015|r02 | R3: =VLOOKUP(D3,Base_Amostral!$A:$G,5,FALSE) -> Alta Floresta D'Oeste | S3: =VLOOKUP(D3,Base_Amostral!$A:$G,3,FALSE) -> Rondônia | T3: =VLOOKUP(D3,Base_Amostral!$A:$G,6,FALSE) -> Norte | U3: =IF(E3="","",E3/10) -> 7 | V3: =IF(H3="","",H3/10) -> 7.2 | W3: =IF(OR(U3="",V3=""),"",U3-V3) -> -0.2 | X3: =IF(OR(U3="",V3=""),"",AVERAGE(U3:V3)) -> 7.1 | Y3: =IF(AND(U3<>"",V3<>""),1,0) -> 1 | Z3: =IF(D3<>D2,"",IF(OR(U3="",U2=""),"",U3-U2)) -> 0 | AA3: =IF(D3<>D2,"",IF(OR(V3="",V2=""),"",V3-V2)) -> 0 | AB3: =IF(B3<>"r04","",IF(COUNT(INDEX(U:U,ROW()-3):U3)<2,"",MAX(INDEX(U:U,ROW()-3):U3)-MIN(INDEX(U:U,ROW()-3):U3))) | AC3: =IF(B3<>"r04","",IF(COUNT(INDEX(V:V,ROW()-3):V3)<2,"",MAX(INDEX(V:V,ROW()-3):V3)-MIN(INDEX(V:V,ROW()-3):V3))) | AD3: =IF(B3<>"r04","",COUNT(INDEX(U:U,ROW()-3):U3)) | AE3: =IF(B3<>"r04","",COUNT(INDEX(V:V,ROW()-3):V3))
A4: 1137 | B4: r03 | C4: 2026-07-06_19-27-44__validacao_tcc_unifal_r03 | D4: 1100015 | E4: 70 | F4: sucesso | G4: 46209.835 | H4: 72 | I4: sucesso | J4: 46209.835 | K4: 1 | L4: 1 | M4: completo | O4: 46209.834 | P4: 46209.835 | Q4: =D4&"|"&B4 -> 1100015|r03 | R4: =VLOOKUP(D4,Base_Amostral!$A:$G,5,FALSE) -> Alta Floresta D'Oeste | S4: =VLOOKUP(D4,Base_Amostral!$A:$G,3,FALSE) -> Rondônia | T4: =VLOOKUP(D4,Base_Amostral!$A:$G,6,FALSE) -> Norte | U4: =IF(E4="","",E4/10) -> 7 | V4: =IF(H4="","",H4/10) -> 7.2 | W4: =IF(OR(U4="",V4=""),"",U4-V4) -> -0.2 | X4: =IF(OR(U4="",V4=""),"",AVERAGE(U4:V4)) -> 7.1 | Y4: =IF(AND(U4<>"",V4<>""),1,0) -> 1 | Z4: =IF(D4<>D3,"",IF(OR(U4="",U3=""),"",U4-U3)) -> 0 | AA4: =IF(D4<>D3,"",IF(OR(V4="",V3=""),"",V4-V3)) -> 0 | AB4: =IF(B4<>"r04","",IF(COUNT(INDEX(U:U,ROW()-3):U4)<2,"",MAX(INDEX(U:U,ROW()-3):U4)-MIN(INDEX(U:U,ROW()-3):U4))) | AC4: =IF(B4<>"r04","",IF(COUNT(INDEX(V:V,ROW()-3):V4)<2,"",MAX(INDEX(V:V,ROW()-3):V4)-MIN(INDEX(V:V,ROW()-3):V4))) | AD4: =IF(B4<>"r04","",COUNT(INDEX(U:U,ROW()-3):U4)) | AE4: =IF(B4<>"r04","",COUNT(INDEX(V:V,ROW()-3):V4))
A5: 1507 | B5: r04 | C5: 2026-07-13_19-07-57__validacao_tcc_unifal_r04 | D5: 1100015 | E5: 80 | F5: sucesso | G5: 46216.817 | H5: 72 | I5: sucesso | J5: 46216.817 | K5: 1 | L5: 1 | M5: completo | O5: 46216.816 | P5: 46216.817 | Q5: =D5&"|"&B5 -> 1100015|r04 | R5: =VLOOKUP(D5,Base_Amostral!$A:$G,5,FALSE) -> Alta Floresta D'Oeste | S5: =VLOOKUP(D5,Base_Amostral!$A:$G,3,FALSE) -> Rondônia | T5: =VLOOKUP(D5,Base_Amostral!$A:$G,6,FALSE) -> Norte | U5: =IF(E5="","",E5/10) -> 8 | V5: =IF(H5="","",H5/10) -> 7.2 | W5: =IF(OR(U5="",V5=""),"",U5-V5) -> 0.8 | X5: =IF(OR(U5="",V5=""),"",AVERAGE(U5:V5)) -> 7.6 | Y5: =IF(AND(U5<>"",V5<>""),1,0) -> 1 | Z5: =IF(D5<>D4,"",IF(OR(U5="",U4=""),"",U5-U4)) -> 1 | AA5: =IF(D5<>D4,"",IF(OR(V5="",V4=""),"",V5-V4)) -> 0 | AB5: =IF(B5<>"r04","",IF(COUNT(INDEX(U:U,ROW()-3):U5)<2,"",MAX(INDEX(U:U,ROW()-3):U5)-MIN(INDEX(U:U,ROW()-3):U5))) -> 1 | AC5: =IF(B5<>"r04","",IF(COUNT(INDEX(V:V,ROW()-3):V5)<2,"",MAX(INDEX(V:V,ROW()-3):V5)-MIN(INDEX(V:V,ROW()-3):V5))) -> 0 | AD5: =IF(B5<>"r04","",COUNT(INDEX(U:U,ROW()-3):U5)) -> 4 | AE5: =IF(B5<>"r04","",COUNT(INDEX(V:V,ROW()-3):V5)) -> 4
A6: 438 | B6: r01 | C6: 2026-06-22_23-12-00__validacao_tcc_unifal_r01 | D6: 1100080 | E6: 65 | F6: sucesso | G6: 46195.997 | H6: 67 | I6: sucesso | J6: 46195.997 | K6: 1 | L6: 1 | M6: completo | O6: 46195.996 | P6: 46195.997 | Q6: =D6&"|"&B6 -> 1100080|r01 | R6: =VLOOKUP(D6,Base_Amostral!$A:$G,5,FALSE) -> Costa Marques | S6: =VLOOKUP(D6,Base_Amostral!$A:$G,3,FALSE) -> Rondônia | T6: =VLOOKUP(D6,Base_Amostral!$A:$G,6,FALSE) -> Norte | U6: =IF(E6="","",E6/10) -> 6.5 | V6: =IF(H6="","",H6/10) -> 6.7 | W6: =IF(OR(U6="",V6=""),"",U6-V6) -> -0.2 | X6: =IF(OR(U6="",V6=""),"",AVERAGE(U6:V6)) -> 6.6 | Y6: =IF(AND(U6<>"",V6<>""),1,0) -> 1 | Z6: =IF(D6<>D5,"",IF(OR(U6="",U5=""),"",U6-U5)) | AA6: =IF(D6<>D5,"",IF(OR(V6="",V5=""),"",V6-V5)) | AB6: =IF(B6<>"r04","",IF(COUNT(INDEX(U:U,ROW()-3):U6)<2,"",MAX(INDEX(U:U,ROW()-3):U6)-MIN(INDEX(U:U,ROW()-3):U6))) | AC6: =IF(B6<>"r04","",IF(COUNT(INDEX(V:V,ROW()-3):V6)<2,"",MAX(INDEX(V:V,ROW()-3):V6)-MIN(INDEX(V:V,ROW()-3):V6))) | AD6: =IF(B6<>"r04","",COUNT(INDEX(U:U,ROW()-3):U6)) | AE6: =IF(B6<>"r04","",COUNT(INDEX(V:V,ROW()-3):V6))
A7: 781 | B7: r02 | C7: 2026-06-30_18-34-12__validacao_tcc_unifal_r02 | D7: 1100080 | E7: 65 | F7: sucesso | G7: 46203.796 | H7: 65 | I7: sucesso | J7: 46203.797 | K7: 1 | L7: 1 | M7: completo | O7: 46203.796 | P7: 46203.797 | Q7: =D7&"|"&B7 -> 1100080|r02 | R7: =VLOOKUP(D7,Base_Amostral!$A:$G,5,FALSE) -> Costa Marques | S7: =VLOOKUP(D7,Base_Amostral!$A:$G,3,FALSE) -> Rondônia | T7: =VLOOKUP(D7,Base_Amostral!$A:$G,6,FALSE) -> Norte | U7: =IF(E7="","",E7/10) -> 6.5 | V7: =IF(H7="","",H7/10) -> 6.5 | W7: =IF(OR(U7="",V7=""),"",U7-V7) -> 0 | X7: =IF(OR(U7="",V7=""),"",AVERAGE(U7:V7)) -> 6.5 | Y7: =IF(AND(U7<>"",V7<>""),1,0) -> 1 | Z7: =IF(D7<>D6,"",IF(OR(U7="",U6=""),"",U7-U6)) -> 0 | AA7: =IF(D7<>D6,"",IF(OR(V7="",V6=""),"",V7-V6)) -> -0.2 | AB7: =IF(B7<>"r04","",IF(COUNT(INDEX(U:U,ROW()-3):U7)<2,"",MAX(INDEX(U:U,ROW()-3):U7)-MIN(INDEX(U:U,ROW()-3):U7))) | AC7: =IF(B7<>"r04","",IF(COUNT(INDEX(V:V,ROW()-3):V7)<2,"",MAX(INDEX(V:V,ROW()-3):V7)-MIN(INDEX(V:V,ROW()-3):V7))) | AD7: =IF(B7<>"r04","",COUNT(INDEX(U:U,ROW()-3):U7)) | AE7: =IF(B7<>"r04","",COUNT(INDEX(V:V,ROW()-3):V7))
A8: 1146 | B8: r03 | C8: 2026-07-06_19-27-44__validacao_tcc_unifal_r03 | D8: 1100080 | E8: 62 | F8: sucesso | G8: 46209.839 | H8: 66 | I8: sucesso | J8: 46209.839 | K8: 1 | L8: 1 | M8: completo | O8: 46209.839 | P8: 46209.839 | Q8: =D8&"|"&B8 -> 1100080|r03 | R8: =VLOOKUP(D8,Base_Amostral!$A:$G,5,FALSE) -> Costa Marques | S8: =VLOOKUP(D8,Base_Amostral!$A:$G,3,FALSE) -> Rondônia | T8: =VLOOKUP(D8,Base_Amostral!$A:$G,6,FALSE) -> Norte | U8: =IF(E8="","",E8/10) -> 6.2 | V8: =IF(H8="","",H8/10) -> 6.6 | W8: =IF(OR(U8="",V8=""),"",U8-V8) -> -0.4 | X8: =IF(OR(U8="",V8=""),"",AVERAGE(U8:V8)) -> 6.4 | Y8: =IF(AND(U8<>"",V8<>""),1,0) -> 1 | Z8: =IF(D8<>D7,"",IF(OR(U8="",U7=""),"",U8-U7)) -> -0.3 | AA8: =IF(D8<>D7,"",IF(OR(V8="",V7=""),"",V8-V7)) -> 0.1 | AB8: =IF(B8<>"r04","",IF(COUNT(INDEX(U:U,ROW()-3):U8)<2,"",MAX(INDEX(U:U,ROW()-3):U8)-MIN(INDEX(U:U,ROW()-3):U8))) | AC8: =IF(B8<>"r04","",IF(COUNT(INDEX(V:V,ROW()-3):V8)<2,"",MAX(INDEX(V:V,ROW()-3):V8)-MIN(INDEX(V:V,ROW()-3):V8))) | AD8: =IF(B8<>"r04","",COUNT(INDEX(U:U,ROW()-3):U8)) | AE8: =IF(B8<>"r04","",COUNT(INDEX(V:V,ROW()-3):V8))
A9: 1516 | B9: r04 | C9: 2026-07-13_19-07-57__validacao_tcc_unifal_r04 | D9: 1100080 | E9: 71 | F9: sucesso | G9: 46216.819 | H9: 66 | I9: sucesso | J9: 46216.819 | K9: 1 | L9: 1 | M9: completo | O9: 46216.818 | P9: 46216.819 | Q9: =D9&"|"&B9 -> 1100080|r04 | R9: =VLOOKUP(D9,Base_Amostral!$A:$G,5,FALSE) -> Costa Marques | S9: =VLOOKUP(D9,Base_Amostral!$A:$G,3,FALSE) -> Rondônia | T9: =VLOOKUP(D9,Base_Amostral!$A:$G,6,FALSE) -> Norte | U9: =IF(E9="","",E9/10) -> 7.1 | V9: =IF(H9="","",H9/10) -> 6.6 | W9: =IF(OR(U9="",V9=""),"",U9-V9) -> 0.5 | X9: =IF(OR(U9="",V9=""),"",AVERAGE(U9:V9)) -> 6.85 | Y9: =IF(AND(U9<>"",V9<>""),1,0) -> 1 | Z9: =IF(D9<>D8,"",IF(OR(U9="",U8=""),"",U9-U8)) -> 0.9 | AA9: =IF(D9<>D8,"",IF(OR(V9="",V8=""),"",V9-V8)) -> 0 | AB9: =IF(B9<>"r04","",IF(COUNT(INDEX(U:U,ROW()-3):U9)<2,"",MAX(INDEX(U:U,ROW()-3):U9)-MIN(INDEX(U:U,ROW()-3):U9))) -> 0.9 | AC9: =IF(B9<>"r04","",IF(COUNT(INDEX(V:V,ROW()-3):V9)<2,"",MAX(INDEX(V:V,ROW()-3):V9)-MIN(INDEX(V:V,ROW()-3):V9))) -> 0.2 | AD9: =IF(B9<>"r04","",COUNT(INDEX(U:U,ROW()-3):U9)) -> 4 | AE9: =IF(B9<>"r04","",COUNT(INDEX(V:V,ROW()-3):V9)) -> 4
